2024-10-10 16:01:29,124 [ERROR]: Internal Server Error: /api/auth/login
Traceback (most recent call last):
  File "C:\Users\JJH\OneDrive - Poyner Spruill\Documents\py\apibe\apiV1\Lib\site-packages\django\core\handlers\exception.py", line 55, in inner
    response = get_response(request)
               ^^^^^^^^^^^^^^^^^^^^^
  File "C:\Users\JJH\OneDrive - Poyner Spruill\Documents\py\apibe\apiV1\Lib\site-packages\django\core\handlers\base.py", line 197, in _get_response
    response = wrapped_callback(request, *callback_args, **callback_kwargs)
               ^^^^^^^^^^^^^^^^^^^^^^^^^^^^^^^^^^^^^^^^^^^^^^^^^^^^^^^^^^^^
  File "C:\Users\JJH\OneDrive - Poyner Spruill\Documents\py\apibe\api\user_system\views.py", line 43, in auth_page
    redirect_uri=request.build_absolute_uri(reverse("getAToken"))
                                           ^^^^^^^
NameError: name 'reverse' is not defined. Did you mean: 'reversed'?
2024-10-10 16:01:29,565 [WARNING]: Not Found: /favicon.ico
2024-10-10 16:02:03,052 [INFO]: C:\Users\JJH\OneDrive - Poyner Spruill\Documents\py\apibe\api\user_system\views.py changed, reloading.
2024-10-10 16:02:43,695 [INFO]: C:\Users\JJH\OneDrive - Poyner Spruill\Documents\py\apibe\api\user_system\views.py changed, reloading.
2024-10-10 16:07:15,188 [INFO]: C:\Users\JJH\OneDrive - Poyner Spruill\Documents\py\apibe\api\user_system\views.py changed, reloading.
2024-10-10 16:07:46,988 [INFO]: C:\Users\JJH\OneDrive - Poyner Spruill\Documents\py\apibe\api\user_system\views.py changed, reloading.
2024-10-10 16:07:55,059 [WARNING]: Bad Request: /api/auth/validation
2024-10-10 16:08:11,917 [WARNING]: Bad Request: /api/auth/validation
2024-10-10 16:08:19,442 [WARNING]: Bad Request: /api/auth/validation
2024-10-10 16:08:59,392 [INFO]: C:\Users\JJH\OneDrive - Poyner Spruill\Documents\py\apibe\api\user_system\views.py changed, reloading.
2024-10-10 16:09:20,800 [INFO]: C:\Users\JJH\OneDrive - Poyner Spruill\Documents\py\apibe\api\user_system\views.py changed, reloading.
2024-10-10 16:09:24,072 [WARNING]: Bad Request: /api/auth/validation
2024-10-10 16:09:33,467 [INFO]: C:\Users\JJH\OneDrive - Poyner Spruill\Documents\py\apibe\api\user_system\views.py changed, reloading.
2024-10-10 16:09:36,789 [WARNING]: Bad Request: /api/auth/validation
2024-10-10 16:09:44,808 [INFO]: C:\Users\JJH\OneDrive - Poyner Spruill\Documents\py\apibe\api\user_system\views.py changed, reloading.
2024-10-10 16:09:49,092 [WARNING]: Bad Request: /api/auth/validation
2024-10-10 16:23:59,308 [WARNING]: Bad Request: /api/auth/validation
2024-10-10 16:25:38,549 [INFO]: C:\Users\JJH\OneDrive - Poyner Spruill\Documents\py\apibe\api\user_system\views.py changed, reloading.
2024-10-10 16:25:44,385 [WARNING]: Forbidden: /api/auth/validation
2024-10-10 16:28:55,944 [INFO]: C:\Users\JJH\OneDrive - Poyner Spruill\Documents\py\apibe\api\user_system\views.py changed, reloading.
2024-10-10 16:36:34,860 [INFO]: C:\Users\JJH\OneDrive - Poyner Spruill\Documents\py\apibe\api\user_system\views.py changed, reloading.
2024-10-10 16:36:40,348 [WARNING]: Forbidden: /api/auth/validation
2024-10-10 16:36:47,815 [WARNING]: Forbidden: /api/auth/validation
2024-10-10 16:38:44,806 [INFO]: C:\Users\JJH\OneDrive - Poyner Spruill\Documents\py\apibe\api\user_system\views.py changed, reloading.
2024-10-10 16:38:48,824 [WARNING]: Forbidden: /api/auth/validation
2024-10-10 16:38:57,228 [WARNING]: Forbidden: /api/auth/validation
2024-10-10 16:39:06,170 [WARNING]: Forbidden: /api/auth/validation
2024-10-10 16:39:23,044 [INFO]: C:\Users\JJH\OneDrive - Poyner Spruill\Documents\py\apibe\api\user_system\views.py changed, reloading.
2024-10-10 18:01:58,646 [INFO]: C:\Users\JJH\OneDrive - Poyner Spruill\Documents\py\apibe\api\user_system\views.py changed, reloading.
2024-10-10 18:02:04,291 [WARNING]: Forbidden: /api/auth/validation
2024-10-10 18:02:05,664 [WARNING]: Forbidden: /api/auth/validation
2024-10-10 18:06:27,938 [WARNING]: Forbidden: /api/auth/validation
2024-10-10 18:06:43,403 [WARNING]: Forbidden: /api/auth/validation
2024-10-10 18:06:49,734 [WARNING]: Forbidden: /api/auth/validation
2024-10-10 18:06:54,959 [WARNING]: Forbidden: /api/auth/validation
2024-10-10 18:07:20,698 [WARNING]: Forbidden: /api/auth/validation
2024-10-10 18:11:03,909 [WARNING]: Forbidden: /api/auth/validation
2024-10-10 18:11:10,111 [WARNING]: Forbidden: /api/auth/validation
2024-10-10 18:11:12,260 [WARNING]: Forbidden: /api/auth/validation
2024-10-10 18:11:59,892 [WARNING]: Forbidden: /api/auth/validation
2024-10-11 10:41:33,609 [INFO]: C:\Users\JJH\OneDrive - Poyner Spruill\Documents\py\apibe\api\user_system\views.py changed, reloading.
2024-10-11 10:55:00,045 [INFO]: C:\Users\JJH\OneDrive - Poyner Spruill\Documents\py\apibe\api\user_system\views.py changed, reloading.
2024-10-11 11:00:58,954 [INFO]: C:\Users\JJH\OneDrive - Poyner Spruill\Documents\py\apibe\api\user_system\views.py changed, reloading.
2024-10-11 11:01:33,836 [INFO]: C:\Users\JJH\OneDrive - Poyner Spruill\Documents\py\apibe\api\user_system\views.py changed, reloading.
2024-10-11 11:04:32,105 [INFO]: C:\Users\JJH\OneDrive - Poyner Spruill\Documents\py\apibe\api\user_system\views.py changed, reloading.
2024-10-11 11:08:33,586 [INFO]: C:\Users\JJH\OneDrive - Poyner Spruill\Documents\py\apibe\api\user_system\views.py changed, reloading.
2024-10-11 11:09:45,613 [INFO]: C:\Users\JJH\OneDrive - Poyner Spruill\Documents\py\apibe\api\user_system\views.py changed, reloading.
2024-10-11 11:10:45,260 [INFO]: C:\Users\JJH\OneDrive - Poyner Spruill\Documents\py\apibe\api\user_system\views.py changed, reloading.
2024-10-11 11:11:16,429 [INFO]: C:\Users\JJH\OneDrive - Poyner Spruill\Documents\py\apibe\api\user_system\views.py changed, reloading.
2024-10-11 11:20:20,054 [ERROR]: Internal Server Error: /api/auth/validation
Traceback (most recent call last):
  File "C:\Users\JJH\OneDrive - Poyner Spruill\Documents\py\apibe\tempV\Lib\site-packages\django\core\handlers\exception.py", line 55, in inner
    response = get_response(request)
               ^^^^^^^^^^^^^^^^^^^^^
  File "C:\Users\JJH\OneDrive - Poyner Spruill\Documents\py\apibe\tempV\Lib\site-packages\django\core\handlers\base.py", line 197, in _get_response
    response = wrapped_callback(request, *callback_args, **callback_kwargs)
               ^^^^^^^^^^^^^^^^^^^^^^^^^^^^^^^^^^^^^^^^^^^^^^^^^^^^^^^^^^^^
  File "C:\Users\JJH\OneDrive - Poyner Spruill\Documents\py\apibe\tempV\Lib\site-packages\django\views\decorators\csrf.py", line 65, in _view_wrapper
    return view_func(request, *args, **kwargs)
           ^^^^^^^^^^^^^^^^^^^^^^^^^^^^^^^^^^^
  File "C:\Users\JJH\OneDrive - Poyner Spruill\Documents\py\apibe\tempV\Lib\site-packages\django\views\generic\base.py", line 104, in view
    return self.dispatch(request, *args, **kwargs)
           ^^^^^^^^^^^^^^^^^^^^^^^^^^^^^^^^^^^^^^^
  File "C:\Users\JJH\OneDrive - Poyner Spruill\Documents\py\apibe\tempV\Lib\site-packages\rest_framework\views.py", line 509, in dispatch
    response = self.handle_exception(exc)
               ^^^^^^^^^^^^^^^^^^^^^^^^^^
  File "C:\Users\JJH\OneDrive - Poyner Spruill\Documents\py\apibe\tempV\Lib\site-packages\rest_framework\views.py", line 469, in handle_exception
    self.raise_uncaught_exception(exc)
  File "C:\Users\JJH\OneDrive - Poyner Spruill\Documents\py\apibe\tempV\Lib\site-packages\rest_framework\views.py", line 480, in raise_uncaught_exception
    raise exc
  File "C:\Users\JJH\OneDrive - Poyner Spruill\Documents\py\apibe\tempV\Lib\site-packages\rest_framework\views.py", line 506, in dispatch
    response = handler(request, *args, **kwargs)
               ^^^^^^^^^^^^^^^^^^^^^^^^^^^^^^^^^
  File "C:\Users\JJH\OneDrive - Poyner Spruill\Documents\py\apibe\tempV\Lib\site-packages\rest_framework\decorators.py", line 50, in handler
    return func(*args, **kwargs)
           ^^^^^^^^^^^^^^^^^^^^^
  File "C:\Users\JJH\OneDrive - Poyner Spruill\Documents\py\apibe\api\user_system\views.py", line 98, in user_validation
    if validating_token.created < (datetime.now() - timedelta(days=1)):
       ^^^^^^^^^^^^^^^^^^^^^^^^^^^^^^^^^^^^^^^^^^^^^^^^^^^^^^^^^^^^^^^
TypeError: can't compare offset-naive and offset-aware datetimes
2024-10-11 11:21:43,832 [INFO]: C:\Users\JJH\OneDrive - Poyner Spruill\Documents\py\apibe\api\user_system\views.py changed, reloading.
2024-10-11 14:51:18,394 [INFO]: C:\Users\JJH\OneDrive - Poyner Spruill\Documents\py\apibe\api\user_system\views.py changed, reloading.
2024-10-18 16:32:25,498 [INFO]: C:\Users\JJH\OneDrive - Poyner Spruill\Documents\py\apibe\api\user_system\views.py changed, reloading.
2024-10-18 16:42:44,249 [INFO]: C:\Users\JJH\OneDrive - Poyner Spruill\Documents\py\apibe\api\user_system\urls.py changed, reloading.
2024-10-18 17:03:21,942 [WARNING]: Forbidden (CSRF cookie not set.): /api/auth/validate_access
2024-10-18 17:03:58,157 [INFO]: C:\Users\JJH\OneDrive - Poyner Spruill\Documents\py\apibe\api\user_system\views.py changed, reloading.
2024-10-18 17:04:23,152 [ERROR]: Internal Server Error: /api/auth/validate_access
Traceback (most recent call last):
  File "C:\Users\JJH\OneDrive - Poyner Spruill\Documents\py\apibe\Venv\Lib\site-packages\django\core\handlers\exception.py", line 55, in inner
    response = get_response(request)
  File "C:\Users\JJH\OneDrive - Poyner Spruill\Documents\py\apibe\Venv\Lib\site-packages\django\core\handlers\base.py", line 197, in _get_response
    response = wrapped_callback(request, *callback_args, **callback_kwargs)
  File "C:\Users\JJH\OneDrive - Poyner Spruill\Documents\py\apibe\Venv\Lib\site-packages\django\views\decorators\csrf.py", line 65, in _view_wrapper
    return view_func(request, *args, **kwargs)
  File "C:\Users\JJH\OneDrive - Poyner Spruill\Documents\py\apibe\Venv\Lib\site-packages\django\views\generic\base.py", line 104, in view
    return self.dispatch(request, *args, **kwargs)
           ~~~~~~~~~~~~~^^^^^^^^^^^^^^^^^^^^^^^^^^
  File "C:\Users\JJH\OneDrive - Poyner Spruill\Documents\py\apibe\Venv\Lib\site-packages\rest_framework\views.py", line 509, in dispatch
    response = self.handle_exception(exc)
  File "C:\Users\JJH\OneDrive - Poyner Spruill\Documents\py\apibe\Venv\Lib\site-packages\rest_framework\views.py", line 469, in handle_exception
    self.raise_uncaught_exception(exc)
    ~~~~~~~~~~~~~~~~~~~~~~~~~~~~~^^^^^
  File "C:\Users\JJH\OneDrive - Poyner Spruill\Documents\py\apibe\Venv\Lib\site-packages\rest_framework\views.py", line 480, in raise_uncaught_exception
    raise exc
  File "C:\Users\JJH\OneDrive - Poyner Spruill\Documents\py\apibe\Venv\Lib\site-packages\rest_framework\views.py", line 506, in dispatch
    response = handler(request, *args, **kwargs)
  File "C:\Users\JJH\OneDrive - Poyner Spruill\Documents\py\apibe\Venv\Lib\site-packages\rest_framework\decorators.py", line 50, in handler
    return func(*args, **kwargs)
  File "C:\Users\JJH\OneDrive - Poyner Spruill\Documents\py\apibe\api\user_system\views.py", line 81, in validate_access
    user_info = result.get('id_token_claims', {})
                ^^^^^^
NameError: name 'result' is not defined
2024-10-18 17:06:21,417 [INFO]: C:\Users\JJH\OneDrive - Poyner Spruill\Documents\py\apibe\api\user_system\views.py changed, reloading.
2024-10-18 17:06:28,684 [ERROR]: Internal Server Error: /api/auth/validate_access
Traceback (most recent call last):
  File "C:\Users\JJH\OneDrive - Poyner Spruill\Documents\py\apibe\Venv\Lib\site-packages\django\core\handlers\exception.py", line 55, in inner
    response = get_response(request)
  File "C:\Users\JJH\OneDrive - Poyner Spruill\Documents\py\apibe\Venv\Lib\site-packages\django\core\handlers\base.py", line 197, in _get_response
    response = wrapped_callback(request, *callback_args, **callback_kwargs)
  File "C:\Users\JJH\OneDrive - Poyner Spruill\Documents\py\apibe\Venv\Lib\site-packages\django\views\decorators\csrf.py", line 65, in _view_wrapper
    return view_func(request, *args, **kwargs)
  File "C:\Users\JJH\OneDrive - Poyner Spruill\Documents\py\apibe\Venv\Lib\site-packages\django\views\generic\base.py", line 104, in view
    return self.dispatch(request, *args, **kwargs)
           ~~~~~~~~~~~~~^^^^^^^^^^^^^^^^^^^^^^^^^^
  File "C:\Users\JJH\OneDrive - Poyner Spruill\Documents\py\apibe\Venv\Lib\site-packages\rest_framework\views.py", line 509, in dispatch
    response = self.handle_exception(exc)
  File "C:\Users\JJH\OneDrive - Poyner Spruill\Documents\py\apibe\Venv\Lib\site-packages\rest_framework\views.py", line 469, in handle_exception
    self.raise_uncaught_exception(exc)
    ~~~~~~~~~~~~~~~~~~~~~~~~~~~~~^^^^^
  File "C:\Users\JJH\OneDrive - Poyner Spruill\Documents\py\apibe\Venv\Lib\site-packages\rest_framework\views.py", line 480, in raise_uncaught_exception
    raise exc
  File "C:\Users\JJH\OneDrive - Poyner Spruill\Documents\py\apibe\Venv\Lib\site-packages\rest_framework\views.py", line 506, in dispatch
    response = handler(request, *args, **kwargs)
  File "C:\Users\JJH\OneDrive - Poyner Spruill\Documents\py\apibe\Venv\Lib\site-packages\rest_framework\decorators.py", line 50, in handler
    return func(*args, **kwargs)
  File "C:\Users\JJH\OneDrive - Poyner Spruill\Documents\py\apibe\api\user_system\views.py", line 86, in validate_access
    user_info = result.get('id_token_claims', {})
                ^^^^^^
NameError: name 'result' is not defined
2024-10-18 17:07:26,092 [INFO]: C:\Users\JJH\OneDrive - Poyner Spruill\Documents\py\apibe\api\user_system\views.py changed, reloading.
2024-10-18 17:08:17,387 [ERROR]: Internal Server Error: /api/auth/validate_access
Traceback (most recent call last):
  File "C:\Users\JJH\OneDrive - Poyner Spruill\Documents\py\apibe\Venv\Lib\site-packages\django\core\handlers\exception.py", line 55, in inner
    response = get_response(request)
  File "C:\Users\JJH\OneDrive - Poyner Spruill\Documents\py\apibe\Venv\Lib\site-packages\django\core\handlers\base.py", line 197, in _get_response
    response = wrapped_callback(request, *callback_args, **callback_kwargs)
  File "C:\Users\JJH\OneDrive - Poyner Spruill\Documents\py\apibe\Venv\Lib\site-packages\django\views\decorators\csrf.py", line 65, in _view_wrapper
    return view_func(request, *args, **kwargs)
  File "C:\Users\JJH\OneDrive - Poyner Spruill\Documents\py\apibe\Venv\Lib\site-packages\django\views\generic\base.py", line 104, in view
    return self.dispatch(request, *args, **kwargs)
           ~~~~~~~~~~~~~^^^^^^^^^^^^^^^^^^^^^^^^^^
  File "C:\Users\JJH\OneDrive - Poyner Spruill\Documents\py\apibe\Venv\Lib\site-packages\rest_framework\views.py", line 509, in dispatch
    response = self.handle_exception(exc)
  File "C:\Users\JJH\OneDrive - Poyner Spruill\Documents\py\apibe\Venv\Lib\site-packages\rest_framework\views.py", line 469, in handle_exception
    self.raise_uncaught_exception(exc)
    ~~~~~~~~~~~~~~~~~~~~~~~~~~~~~^^^^^
  File "C:\Users\JJH\OneDrive - Poyner Spruill\Documents\py\apibe\Venv\Lib\site-packages\rest_framework\views.py", line 480, in raise_uncaught_exception
    raise exc
  File "C:\Users\JJH\OneDrive - Poyner Spruill\Documents\py\apibe\Venv\Lib\site-packages\rest_framework\views.py", line 506, in dispatch
    response = handler(request, *args, **kwargs)
  File "C:\Users\JJH\OneDrive - Poyner Spruill\Documents\py\apibe\Venv\Lib\site-packages\rest_framework\decorators.py", line 50, in handler
    return func(*args, **kwargs)
  File "C:\Users\JJH\OneDrive - Poyner Spruill\Documents\py\apibe\api\user_system\views.py", line 86, in validate_access
    user_info = result.get('id_token_claims', {})
                ^^^^^^
NameError: name 'result' is not defined
2024-10-18 17:08:44,454 [INFO]: C:\Users\JJH\OneDrive - Poyner Spruill\Documents\py\apibe\api\user_system\views.py changed, reloading.
2024-10-18 17:09:27,090 [INFO]: C:\Users\JJH\OneDrive - Poyner Spruill\Documents\py\apibe\api\user_system\views.py changed, reloading.
2024-10-18 17:10:35,088 [INFO]: C:\Users\JJH\OneDrive - Poyner Spruill\Documents\py\apibe\api\user_system\views.py changed, reloading.
2024-10-18 17:10:55,490 [INFO]: C:\Users\JJH\OneDrive - Poyner Spruill\Documents\py\apibe\api\user_system\views.py changed, reloading.
2024-10-18 17:12:15,890 [INFO]: C:\Users\JJH\OneDrive - Poyner Spruill\Documents\py\apibe\api\user_system\views.py changed, reloading.
2024-10-18 17:17:42,755 [INFO]: C:\Users\JJH\OneDrive - Poyner Spruill\Documents\py\apibe\api\user_system\views.py changed, reloading.
2024-10-18 17:19:23,188 [WARNING]: Unauthorized: /api/auth/validation
2024-10-18 17:19:42,704 [WARNING]: Unauthorized: /api/auth/validation
2024-10-18 17:22:07,447 [WARNING]: Unauthorized: /api/auth/validation
2024-10-18 17:23:04,950 [WARNING]: Unauthorized: /api/auth/validation
2024-10-18 22:14:37,826 [INFO]: C:\Users\JJH\OneDrive - Poyner Spruill\Documents\py\apibe\api\user_system\views.py changed, reloading.
2024-10-18 22:14:49,423 [WARNING]: Unauthorized: /api/auth/validation
2024-10-18 22:15:57,016 [INFO]: C:\Users\JJH\OneDrive - Poyner Spruill\Documents\py\apibe\api\user_system\views.py changed, reloading.
2024-10-18 22:16:12,781 [WARNING]: Unauthorized: /api/auth/validation
2024-10-18 23:30:39,528 [INFO]: C:\Users\JJH\OneDrive - Poyner Spruill\Documents\py\apibe\api\user_system\views.py changed, reloading.
2024-10-18 23:30:48,056 [INFO]: C:\Users\JJH\OneDrive - Poyner Spruill\Documents\py\apibe\api\user_system\views.py changed, reloading.
2024-10-18 23:32:42,908 [WARNING]: Unauthorized: /api/auth/validation
2024-10-18 23:32:43,280 [WARNING]: Not Found: /favicon.ico
2024-10-19 00:10:15,934 [WARNING]: Unauthorized: /api/auth/validation
2024-10-19 01:10:40,670 [INFO]: C:\Users\JJH\OneDrive - Poyner Spruill\Documents\py\apibe\api\user_system\views.py changed, reloading.
2024-10-19 01:10:58,956 [INFO]: C:\Users\JJH\OneDrive - Poyner Spruill\Documents\py\apibe\api\user_system\views.py changed, reloading.
2024-10-19 01:11:04,156 [INFO]: C:\Users\JJH\OneDrive - Poyner Spruill\Documents\py\apibe\api\user_system\views.py changed, reloading.
2024-10-19 01:19:35,939 [INFO]: C:\Users\JJH\OneDrive - Poyner Spruill\Documents\py\apibe\api\user_system\views.py changed, reloading.
2024-10-19 01:19:54,124 [ERROR]: Internal Server Error: /api/auth/validate_access
Traceback (most recent call last):
  File "C:\Users\JJH\OneDrive - Poyner Spruill\Documents\py\apibe\Venv\Lib\site-packages\django\core\handlers\exception.py", line 55, in inner
    response = get_response(request)
  File "C:\Users\JJH\OneDrive - Poyner Spruill\Documents\py\apibe\Venv\Lib\site-packages\django\core\handlers\base.py", line 197, in _get_response
    response = wrapped_callback(request, *callback_args, **callback_kwargs)
  File "C:\Users\JJH\OneDrive - Poyner Spruill\Documents\py\apibe\Venv\Lib\site-packages\django\views\decorators\csrf.py", line 65, in _view_wrapper
    return view_func(request, *args, **kwargs)
  File "C:\Users\JJH\OneDrive - Poyner Spruill\Documents\py\apibe\Venv\Lib\site-packages\django\views\generic\base.py", line 104, in view
    return self.dispatch(request, *args, **kwargs)
           ~~~~~~~~~~~~~^^^^^^^^^^^^^^^^^^^^^^^^^^
  File "C:\Users\JJH\OneDrive - Poyner Spruill\Documents\py\apibe\Venv\Lib\site-packages\rest_framework\views.py", line 509, in dispatch
    response = self.handle_exception(exc)
  File "C:\Users\JJH\OneDrive - Poyner Spruill\Documents\py\apibe\Venv\Lib\site-packages\rest_framework\views.py", line 469, in handle_exception
    self.raise_uncaught_exception(exc)
    ~~~~~~~~~~~~~~~~~~~~~~~~~~~~~^^^^^
  File "C:\Users\JJH\OneDrive - Poyner Spruill\Documents\py\apibe\Venv\Lib\site-packages\rest_framework\views.py", line 480, in raise_uncaught_exception
    raise exc
  File "C:\Users\JJH\OneDrive - Poyner Spruill\Documents\py\apibe\Venv\Lib\site-packages\rest_framework\views.py", line 506, in dispatch
    response = handler(request, *args, **kwargs)
  File "C:\Users\JJH\OneDrive - Poyner Spruill\Documents\py\apibe\Venv\Lib\site-packages\rest_framework\decorators.py", line 50, in handler
    return func(*args, **kwargs)
  File "C:\Users\JJH\OneDrive - Poyner Spruill\Documents\py\apibe\api\user_system\views.py", line 93, in validate_access
    login(requests, valid_user, backend='django.contrib.auth.backends.ModelBackend')
    ~~~~~^^^^^^^^^^^^^^^^^^^^^^^^^^^^^^^^^^^^^^^^^^^^^^^^^^^^^^^^^^^^^^^^^^^^^^^^^^^
  File "C:\Users\JJH\OneDrive - Poyner Spruill\Documents\py\apibe\Venv\Lib\site-packages\django\contrib\auth\__init__.py", line 114, in login
    if SESSION_KEY in request.session:
       ^^^^^^^^^^^^^^^^^^^^^^^^^^^^^^
TypeError: argument of type 'function' is not iterable
2024-10-19 01:20:55,329 [INFO]: C:\Users\JJH\OneDrive - Poyner Spruill\Documents\py\apibe\api\user_system\views.py changed, reloading.
2024-10-19 01:21:01,266 [WARNING]: Unauthorized: /api/auth/validation
2024-10-19 01:21:28,311 [INFO]: C:\Users\JJH\OneDrive - Poyner Spruill\Documents\py\apibe\api\user_system\views.py changed, reloading.
2024-10-19 01:21:41,138 [WARNING]: Unauthorized: /api/auth/validation
2024-10-19 01:22:05,387 [INFO]: C:\Users\JJH\OneDrive - Poyner Spruill\Documents\py\apibe\api\user_system\views.py changed, reloading.
2024-10-19 01:22:24,624 [WARNING]: Unauthorized: /api/auth/validation
2024-10-19 01:33:31,397 [INFO]: C:\Users\JJH\OneDrive - Poyner Spruill\Documents\py\apibe\api\user_system\views.py changed, reloading.
2024-10-19 01:33:57,694 [WARNING]: Unauthorized: /api/auth/validation
2024-10-19 01:35:33,558 [INFO]: C:\Users\JJH\OneDrive - Poyner Spruill\Documents\py\apibe\api\user_system\views.py changed, reloading.
2024-10-19 01:35:47,960 [INFO]: C:\Users\JJH\OneDrive - Poyner Spruill\Documents\py\apibe\api\user_system\views.py changed, reloading.
2024-10-19 01:35:59,475 [WARNING]: Unauthorized: /api/auth/validation
2024-10-19 01:36:32,432 [INFO]: C:\Users\JJH\OneDrive - Poyner Spruill\Documents\py\apibe\api\user_system\views.py changed, reloading.
2024-10-19 01:36:43,396 [WARNING]: Unauthorized: /api/auth/validation
2024-10-19 01:37:22,226 [INFO]: C:\Users\JJH\OneDrive - Poyner Spruill\Documents\py\apibe\api\user_system\views.py changed, reloading.
2024-10-19 01:37:32,770 [WARNING]: Unauthorized: /api/auth/validation
2024-10-19 01:38:01,274 [INFO]: C:\Users\JJH\OneDrive - Poyner Spruill\Documents\py\apibe\api\user_system\views.py changed, reloading.
2024-10-19 01:43:29,723 [WARNING]: Unauthorized: /api/auth/validation
2024-10-19 01:45:39,643 [INFO]: C:\Users\JJH\OneDrive - Poyner Spruill\Documents\py\apibe\api\api\dev.py changed, reloading.
2024-10-19 01:55:00,276 [INFO]: C:\Users\JJH\OneDrive - Poyner Spruill\Documents\py\apibe\api\api\dev.py changed, reloading.
2024-10-19 01:55:11,516 [WARNING]: Unauthorized: /api/auth/validation
2024-10-19 02:06:08,663 [INFO]: C:\Users\JJH\OneDrive - Poyner Spruill\Documents\py\apibe\api\user_system\views.py changed, reloading.
2024-10-19 02:06:19,386 [WARNING]: Unauthorized: /api/auth/validation
2024-10-19 03:40:34,599 [WARNING]: Unauthorized: /api/auth/validation
2024-10-19 03:41:53,169 [WARNING]: Unauthorized: /api/auth/validation
2024-10-19 10:50:26,112 [WARNING]: Unauthorized: /api/auth/validation
2024-10-19 11:04:57,527 [WARNING]: Unauthorized: /api/auth/validation
2024-10-19 11:05:05,954 [WARNING]: Unauthorized: /api/auth/validation
2024-10-19 11:08:34,306 [WARNING]: Unauthorized: /api/auth/validation
2024-10-19 18:00:27,828 [WARNING]: Unauthorized: /api/auth/validation
2024-10-19 18:01:01,585 [WARNING]: Unauthorized: /api/auth/validation
2024-10-19 18:03:25,725 [WARNING]: Unauthorized: /api/auth/validation
2024-10-19 18:03:35,475 [WARNING]: Unauthorized: /api/auth/validation
2024-10-19 18:19:34,209 [WARNING]: Unauthorized: /api/auth/validation
2024-10-19 18:22:44,960 [WARNING]: Unauthorized: /api/auth/validation
2024-10-19 18:27:25,118 [INFO]: C:\Users\JJH\OneDrive - Poyner Spruill\Documents\py\apibe\api\api\dev.py changed, reloading.
2024-10-19 18:32:06,051 [INFO]: C:\Users\JJH\OneDrive - Poyner Spruill\Documents\py\apibe\api\user_system\views.py changed, reloading.
2024-10-19 18:32:59,277 [INFO]: C:\Users\JJH\OneDrive - Poyner Spruill\Documents\py\apibe\api\user_system\views.py changed, reloading.
2024-10-19 18:34:15,117 [WARNING]: Unauthorized: /api/auth/validation
2024-10-19 18:35:26,424 [WARNING]: Unauthorized: /api/auth/validation
2024-10-19 18:35:45,926 [WARNING]: Unauthorized: /api/auth/validation
2024-10-19 18:35:50,702 [WARNING]: Unauthorized: /api/auth/validation
2024-10-19 18:36:48,146 [WARNING]: Unauthorized: /api/auth/validation
2024-10-19 18:50:43,945 [WARNING]: Unauthorized: /api/auth/validation
2024-10-19 18:51:00,970 [WARNING]: Unauthorized: /api/auth/validation
2024-10-19 18:54:29,560 [WARNING]: Unauthorized: /api/auth/validation
2024-10-19 18:56:40,577 [WARNING]: Unauthorized: /api/auth/validation
2024-10-19 19:00:41,376 [WARNING]: Unauthorized: /api/auth/validation
2024-10-19 19:02:16,938 [WARNING]: Unauthorized: /api/auth/validation
2024-10-19 19:03:34,824 [WARNING]: Unauthorized: /api/auth/validation
2024-10-19 19:05:02,954 [WARNING]: Unauthorized: /api/auth/validation
2024-10-19 19:09:28,659 [WARNING]: Unauthorized: /api/auth/validation
2024-10-19 19:09:56,424 [WARNING]: Unauthorized: /api/auth/validation
2024-10-19 19:10:15,215 [WARNING]: Unauthorized: /api/auth/validation
2024-10-19 19:10:52,886 [INFO]: C:\Users\JJH\OneDrive - Poyner Spruill\Documents\py\apibe\api\user_system\views.py changed, reloading.
2024-10-19 19:11:02,026 [WARNING]: Forbidden: /api/auth/validation
2024-10-19 21:11:54,627 [WARNING]: Forbidden: /api/auth/validation
2024-10-19 21:12:34,694 [INFO]: C:\Users\JJH\OneDrive - Poyner Spruill\Documents\py\apibe\api\api\dev.py changed, reloading.
2024-10-19 21:12:45,083 [ERROR]: Internal Server Error: /api/auth/validate_access
Traceback (most recent call last):
  File "C:\Users\JJH\OneDrive - Poyner Spruill\Documents\py\apibe\Venv\Lib\site-packages\django\core\handlers\exception.py", line 55, in inner
    response = get_response(request)
  File "C:\Users\JJH\OneDrive - Poyner Spruill\Documents\py\apibe\Venv\Lib\site-packages\django\core\handlers\base.py", line 197, in _get_response
    response = wrapped_callback(request, *callback_args, **callback_kwargs)
  File "C:\Users\JJH\OneDrive - Poyner Spruill\Documents\py\apibe\Venv\Lib\site-packages\django\views\decorators\csrf.py", line 65, in _view_wrapper
    return view_func(request, *args, **kwargs)
  File "C:\Users\JJH\OneDrive - Poyner Spruill\Documents\py\apibe\Venv\Lib\site-packages\django\views\generic\base.py", line 104, in view
    return self.dispatch(request, *args, **kwargs)
           ~~~~~~~~~~~~~^^^^^^^^^^^^^^^^^^^^^^^^^^
  File "C:\Users\JJH\OneDrive - Poyner Spruill\Documents\py\apibe\Venv\Lib\site-packages\rest_framework\views.py", line 509, in dispatch
    response = self.handle_exception(exc)
  File "C:\Users\JJH\OneDrive - Poyner Spruill\Documents\py\apibe\Venv\Lib\site-packages\rest_framework\views.py", line 469, in handle_exception
    self.raise_uncaught_exception(exc)
    ~~~~~~~~~~~~~~~~~~~~~~~~~~~~~^^^^^
  File "C:\Users\JJH\OneDrive - Poyner Spruill\Documents\py\apibe\Venv\Lib\site-packages\rest_framework\views.py", line 480, in raise_uncaught_exception
    raise exc
  File "C:\Users\JJH\OneDrive - Poyner Spruill\Documents\py\apibe\Venv\Lib\site-packages\rest_framework\views.py", line 506, in dispatch
    response = handler(request, *args, **kwargs)
  File "C:\Users\JJH\OneDrive - Poyner Spruill\Documents\py\apibe\Venv\Lib\site-packages\rest_framework\decorators.py", line 50, in handler
    return func(*args, **kwargs)
  File "C:\Users\JJH\OneDrive - Poyner Spruill\Documents\py\apibe\api\user_system\views.py", line 88, in validate_access
    valid_user, created = User.objects.get_or_create(username=api_result["mail"])
                                                              ~~~~~~~~~~^^^^^^^^
KeyError: 'mail'
2024-10-19 21:13:09,565 [WARNING]: Forbidden: /api/auth/validation
2024-10-19 21:17:50,231 [INFO]: C:\Users\JJH\OneDrive - Poyner Spruill\Documents\py\apibe\api\user_system\views.py changed, reloading.
2024-10-19 21:18:00,393 [ERROR]: Internal Server Error: /api/auth/validate_access
Traceback (most recent call last):
  File "C:\Users\JJH\OneDrive - Poyner Spruill\Documents\py\apibe\Venv\Lib\site-packages\django\core\handlers\exception.py", line 55, in inner
    response = get_response(request)
  File "C:\Users\JJH\OneDrive - Poyner Spruill\Documents\py\apibe\Venv\Lib\site-packages\django\core\handlers\base.py", line 197, in _get_response
    response = wrapped_callback(request, *callback_args, **callback_kwargs)
  File "C:\Users\JJH\OneDrive - Poyner Spruill\Documents\py\apibe\Venv\Lib\site-packages\django\views\decorators\csrf.py", line 65, in _view_wrapper
    return view_func(request, *args, **kwargs)
  File "C:\Users\JJH\OneDrive - Poyner Spruill\Documents\py\apibe\Venv\Lib\site-packages\django\views\generic\base.py", line 104, in view
    return self.dispatch(request, *args, **kwargs)
           ~~~~~~~~~~~~~^^^^^^^^^^^^^^^^^^^^^^^^^^
  File "C:\Users\JJH\OneDrive - Poyner Spruill\Documents\py\apibe\Venv\Lib\site-packages\rest_framework\views.py", line 509, in dispatch
    response = self.handle_exception(exc)
  File "C:\Users\JJH\OneDrive - Poyner Spruill\Documents\py\apibe\Venv\Lib\site-packages\rest_framework\views.py", line 469, in handle_exception
    self.raise_uncaught_exception(exc)
    ~~~~~~~~~~~~~~~~~~~~~~~~~~~~~^^^^^
  File "C:\Users\JJH\OneDrive - Poyner Spruill\Documents\py\apibe\Venv\Lib\site-packages\rest_framework\views.py", line 480, in raise_uncaught_exception
    raise exc
  File "C:\Users\JJH\OneDrive - Poyner Spruill\Documents\py\apibe\Venv\Lib\site-packages\rest_framework\views.py", line 506, in dispatch
    response = handler(request, *args, **kwargs)
  File "C:\Users\JJH\OneDrive - Poyner Spruill\Documents\py\apibe\Venv\Lib\site-packages\rest_framework\decorators.py", line 50, in handler
    return func(*args, **kwargs)
  File "C:\Users\JJH\OneDrive - Poyner Spruill\Documents\py\apibe\api\user_system\views.py", line 94, in validate_access
    login(request, valid_user.id, backend='django.contrib.auth.backends.ModelBackend')
    ~~~~~^^^^^^^^^^^^^^^^^^^^^^^^^^^^^^^^^^^^^^^^^^^^^^^^^^^^^^^^^^^^^^^^^^^^^^^^^^^^^
  File "C:\Users\JJH\OneDrive - Poyner Spruill\Documents\py\apibe\Venv\Lib\site-packages\django\contrib\auth\__init__.py", line 146, in login
    request.session[SESSION_KEY] = user._meta.pk.value_to_string(user)
                                   ^^^^^^^^^^
AttributeError: 'int' object has no attribute '_meta'
2024-10-19 21:18:30,203 [ERROR]: Internal Server Error: /api/auth/validate_access
Traceback (most recent call last):
  File "C:\Users\JJH\OneDrive - Poyner Spruill\Documents\py\apibe\Venv\Lib\site-packages\django\core\handlers\exception.py", line 55, in inner
    response = get_response(request)
  File "C:\Users\JJH\OneDrive - Poyner Spruill\Documents\py\apibe\Venv\Lib\site-packages\django\core\handlers\base.py", line 197, in _get_response
    response = wrapped_callback(request, *callback_args, **callback_kwargs)
  File "C:\Users\JJH\OneDrive - Poyner Spruill\Documents\py\apibe\Venv\Lib\site-packages\django\views\decorators\csrf.py", line 65, in _view_wrapper
    return view_func(request, *args, **kwargs)
  File "C:\Users\JJH\OneDrive - Poyner Spruill\Documents\py\apibe\Venv\Lib\site-packages\django\views\generic\base.py", line 104, in view
    return self.dispatch(request, *args, **kwargs)
           ~~~~~~~~~~~~~^^^^^^^^^^^^^^^^^^^^^^^^^^
  File "C:\Users\JJH\OneDrive - Poyner Spruill\Documents\py\apibe\Venv\Lib\site-packages\rest_framework\views.py", line 509, in dispatch
    response = self.handle_exception(exc)
  File "C:\Users\JJH\OneDrive - Poyner Spruill\Documents\py\apibe\Venv\Lib\site-packages\rest_framework\views.py", line 469, in handle_exception
    self.raise_uncaught_exception(exc)
    ~~~~~~~~~~~~~~~~~~~~~~~~~~~~~^^^^^
  File "C:\Users\JJH\OneDrive - Poyner Spruill\Documents\py\apibe\Venv\Lib\site-packages\rest_framework\views.py", line 480, in raise_uncaught_exception
    raise exc
  File "C:\Users\JJH\OneDrive - Poyner Spruill\Documents\py\apibe\Venv\Lib\site-packages\rest_framework\views.py", line 506, in dispatch
    response = handler(request, *args, **kwargs)
  File "C:\Users\JJH\OneDrive - Poyner Spruill\Documents\py\apibe\Venv\Lib\site-packages\rest_framework\decorators.py", line 50, in handler
    return func(*args, **kwargs)
  File "C:\Users\JJH\OneDrive - Poyner Spruill\Documents\py\apibe\api\user_system\views.py", line 94, in validate_access
    login(request, valid_user.id, backend='django.contrib.auth.backends.ModelBackend')
    ~~~~~^^^^^^^^^^^^^^^^^^^^^^^^^^^^^^^^^^^^^^^^^^^^^^^^^^^^^^^^^^^^^^^^^^^^^^^^^^^^^
  File "C:\Users\JJH\OneDrive - Poyner Spruill\Documents\py\apibe\Venv\Lib\site-packages\django\contrib\auth\__init__.py", line 146, in login
    request.session[SESSION_KEY] = user._meta.pk.value_to_string(user)
                                   ^^^^^^^^^^
AttributeError: 'int' object has no attribute '_meta'
2024-10-19 22:02:19,950 [INFO]: C:\Users\JJH\OneDrive - Poyner Spruill\Documents\py\apibe\api\user_system\views.py changed, reloading.
2024-10-19 22:02:38,622 [WARNING]: Forbidden: /api/auth/validation
2024-10-19 22:03:59,304 [INFO]: C:\Users\JJH\OneDrive - Poyner Spruill\Documents\py\apibe\api\user_system\views.py changed, reloading.
2024-10-19 22:04:35,691 [INFO]: C:\Users\JJH\OneDrive - Poyner Spruill\Documents\py\apibe\api\user_system\views.py changed, reloading.
2024-10-19 22:06:13,705 [INFO]: C:\Users\JJH\OneDrive - Poyner Spruill\Documents\py\apibe\api\user_system\views.py changed, reloading.
2024-10-19 22:06:17,856 [WARNING]: Forbidden: /api/auth/validation
2024-10-19 22:06:27,500 [INFO]: C:\Users\JJH\OneDrive - Poyner Spruill\Documents\py\apibe\api\user_system\views.py changed, reloading.
2024-10-19 22:07:44,733 [INFO]: C:\Users\JJH\OneDrive - Poyner Spruill\Documents\py\apibe\api\user_system\views.py changed, reloading.
2024-10-19 22:18:50,945 [INFO]: C:\Users\JJH\OneDrive - Poyner Spruill\Documents\py\apibe\api\user_system\views.py changed, reloading.
2024-10-19 22:20:01,647 [INFO]: C:\Users\JJH\OneDrive - Poyner Spruill\Documents\py\apibe\api\user_system\views.py changed, reloading.
2024-10-19 22:20:16,536 [INFO]: C:\Users\JJH\OneDrive - Poyner Spruill\Documents\py\apibe\api\user_system\views.py changed, reloading.
2024-10-19 22:20:22,375 [INFO]: C:\Users\JJH\OneDrive - Poyner Spruill\Documents\py\apibe\api\user_system\views.py changed, reloading.
2024-10-19 22:28:16,943 [INFO]: C:\Users\JJH\OneDrive - Poyner Spruill\Documents\py\apibe\api\user_system\views.py changed, reloading.
2024-10-19 22:28:24,087 [WARNING]: Forbidden: /api/auth/validation
2024-10-19 22:34:01,841 [INFO]: C:\Users\JJH\OneDrive - Poyner Spruill\Documents\py\apibe\api\user_system\views.py changed, reloading.
2024-10-19 22:36:07,126 [INFO]: C:\Users\JJH\OneDrive - Poyner Spruill\Documents\py\apibe\api\api\dev.py changed, reloading.
2024-10-19 22:36:11,045 [WARNING]: Forbidden: /api/auth/validation
2024-10-19 22:36:28,799 [WARNING]: Forbidden: /api/auth/validation
2024-10-19 22:36:37,770 [INFO]: C:\Users\JJH\OneDrive - Poyner Spruill\Documents\py\apibe\api\user_system\views.py changed, reloading.
2024-10-19 22:36:44,912 [WARNING]: Forbidden: /api/auth/validation
2024-10-19 22:38:46,261 [INFO]: C:\Users\JJH\OneDrive - Poyner Spruill\Documents\py\apibe\api\user_system\views.py changed, reloading.
2024-10-19 22:39:17,161 [INFO]: C:\Users\JJH\OneDrive - Poyner Spruill\Documents\py\apibe\api\api\dev.py changed, reloading.
2024-10-19 22:39:20,955 [WARNING]: Unauthorized: /api/auth/validation
2024-10-19 22:39:34,254 [WARNING]: Unauthorized: /api/auth/validation
2024-10-19 22:40:14,484 [INFO]: C:\Users\JJH\OneDrive - Poyner Spruill\Documents\py\apibe\api\user_system\views.py changed, reloading.
2024-10-19 22:41:12,255 [INFO]: C:\Users\JJH\OneDrive - Poyner Spruill\Documents\py\apibe\api\user_system\views.py changed, reloading.
2024-10-19 22:41:24,436 [WARNING]: Forbidden: /api/auth/validation
2024-10-19 22:41:46,963 [INFO]: C:\Users\JJH\OneDrive - Poyner Spruill\Documents\py\apibe\api\user_system\views.py changed, reloading.
2024-10-19 22:45:18,780 [INFO]: C:\Users\JJH\OneDrive - Poyner Spruill\Documents\py\apibe\api\user_system\views.py changed, reloading.
2024-10-19 22:45:25,407 [WARNING]: Forbidden: /api/auth/validation
2024-10-19 22:45:45,638 [INFO]: C:\Users\JJH\OneDrive - Poyner Spruill\Documents\py\apibe\api\user_system\views.py changed, reloading.
2024-10-19 22:46:01,319 [WARNING]: Forbidden: /api/auth/validation
2024-10-19 22:46:28,997 [INFO]: C:\Users\JJH\OneDrive - Poyner Spruill\Documents\py\apibe\api\user_system\views.py changed, reloading.
2024-10-19 22:47:08,322 [INFO]: C:\Users\JJH\OneDrive - Poyner Spruill\Documents\py\apibe\api\user_system\views.py changed, reloading.
2024-10-19 22:47:28,776 [WARNING]: Forbidden: /api/auth/validation
2024-10-19 22:48:31,441 [INFO]: C:\Users\JJH\OneDrive - Poyner Spruill\Documents\py\apibe\api\user_system\views.py changed, reloading.
2024-10-19 22:51:04,238 [WARNING]: Forbidden: /api/auth/validation
2024-10-19 22:51:57,767 [WARNING]: Forbidden: /api/auth/validation
2024-10-19 22:56:25,358 [INFO]: C:\Users\JJH\OneDrive - Poyner Spruill\Documents\py\apibe\api\user_system\views.py changed, reloading.
2024-10-19 22:57:46,869 [WARNING]: Forbidden: /api/auth/validation
2024-10-19 23:00:31,756 [WARNING]: Forbidden: /api/auth/validation
2024-10-19 23:00:46,191 [INFO]: C:\Users\JJH\OneDrive - Poyner Spruill\Documents\py\apibe\api\user_system\views.py changed, reloading.
2024-10-19 23:03:35,016 [INFO]: C:\Users\JJH\OneDrive - Poyner Spruill\Documents\py\apibe\api\user_system\views.py changed, reloading.
2024-10-19 23:03:42,178 [INFO]: C:\Users\JJH\OneDrive - Poyner Spruill\Documents\py\apibe\api\user_system\views.py changed, reloading.
2024-10-19 23:03:55,152 [ERROR]: Internal Server Error: /api/auth/validation
Traceback (most recent call last):
  File "C:\Users\JJH\OneDrive - Poyner Spruill\Documents\py\apibe\Venv\Lib\site-packages\django\core\handlers\exception.py", line 55, in inner
    response = get_response(request)
  File "C:\Users\JJH\OneDrive - Poyner Spruill\Documents\py\apibe\Venv\Lib\site-packages\django\core\handlers\base.py", line 197, in _get_response
    response = wrapped_callback(request, *callback_args, **callback_kwargs)
  File "C:\Users\JJH\OneDrive - Poyner Spruill\Documents\py\apibe\Venv\Lib\site-packages\django\views\decorators\csrf.py", line 65, in _view_wrapper
    return view_func(request, *args, **kwargs)
  File "C:\Users\JJH\OneDrive - Poyner Spruill\Documents\py\apibe\Venv\Lib\site-packages\django\views\generic\base.py", line 104, in view
    return self.dispatch(request, *args, **kwargs)
           ~~~~~~~~~~~~~^^^^^^^^^^^^^^^^^^^^^^^^^^
  File "C:\Users\JJH\OneDrive - Poyner Spruill\Documents\py\apibe\Venv\Lib\site-packages\rest_framework\views.py", line 509, in dispatch
    response = self.handle_exception(exc)
  File "C:\Users\JJH\OneDrive - Poyner Spruill\Documents\py\apibe\Venv\Lib\site-packages\rest_framework\views.py", line 469, in handle_exception
    self.raise_uncaught_exception(exc)
    ~~~~~~~~~~~~~~~~~~~~~~~~~~~~~^^^^^
  File "C:\Users\JJH\OneDrive - Poyner Spruill\Documents\py\apibe\Venv\Lib\site-packages\rest_framework\views.py", line 480, in raise_uncaught_exception
    raise exc
  File "C:\Users\JJH\OneDrive - Poyner Spruill\Documents\py\apibe\Venv\Lib\site-packages\rest_framework\views.py", line 506, in dispatch
    response = handler(request, *args, **kwargs)
  File "C:\Users\JJH\OneDrive - Poyner Spruill\Documents\py\apibe\Venv\Lib\site-packages\rest_framework\decorators.py", line 50, in handler
    return func(*args, **kwargs)
  File "C:\Users\JJH\OneDrive - Poyner Spruill\Documents\py\apibe\api\user_system\views.py", line 118, in user_validation
    return Response(data=user.data, status=status.HTTP_200_OK)
                         ^^^^^^^^^
AttributeError: 'User' object has no attribute 'data'
2024-10-19 23:04:09,488 [INFO]: C:\Users\JJH\OneDrive - Poyner Spruill\Documents\py\apibe\api\user_system\views.py changed, reloading.
2024-10-19 23:04:44,361 [INFO]: C:\Users\JJH\OneDrive - Poyner Spruill\Documents\py\apibe\api\user_system\views.py changed, reloading.
2024-10-19 23:15:44,727 [INFO]: C:\Users\JJH\OneDrive - Poyner Spruill\Documents\py\apibe\api\user_system\models.py changed, reloading.
2024-10-19 23:17:38,738 [INFO]: C:\Users\JJH\OneDrive - Poyner Spruill\Documents\py\apibe\api\user_system\models.py changed, reloading.
2024-10-19 23:19:34,532 [INFO]: C:\Users\JJH\OneDrive - Poyner Spruill\Documents\py\apibe\api\user_system\views.py changed, reloading.
2024-10-19 23:20:16,490 [INFO]: C:\Users\JJH\OneDrive - Poyner Spruill\Documents\py\apibe\api\user_system\views.py changed, reloading.
2024-10-19 23:21:01,688 [INFO]: C:\Users\JJH\OneDrive - Poyner Spruill\Documents\py\apibe\api\user_system\views.py changed, reloading.
2024-10-19 23:21:05,506 [WARNING]: Unauthorized: /api/auth/validation
2024-10-19 23:22:33,041 [WARNING]: Unauthorized: /api/auth/validation
2024-10-19 23:22:46,919 [WARNING]: Unauthorized: /api/auth/validation
2024-10-19 23:23:51,311 [INFO]: C:\Users\JJH\OneDrive - Poyner Spruill\Documents\py\apibe\api\user_system\views.py changed, reloading.
2024-10-19 23:25:31,550 [INFO]: C:\Users\JJH\OneDrive - Poyner Spruill\Documents\py\apibe\api\user_system\views.py changed, reloading.
2024-10-19 23:25:35,371 [WARNING]: Unauthorized: /api/auth/validation
2024-10-19 23:25:41,123 [WARNING]: Unauthorized: /api/auth/validation
2024-10-19 23:26:56,535 [INFO]: C:\Users\JJH\OneDrive - Poyner Spruill\Documents\py\apibe\api\user_system\models.py changed, reloading.
2024-10-19 23:33:50,263 [INFO]: C:\Users\JJH\OneDrive - Poyner Spruill\Documents\py\apibe\api\user_system\views.py changed, reloading.
2024-10-19 23:34:41,743 [ERROR]: Internal Server Error: /api/auth/getAToken
Traceback (most recent call last):
  File "C:\Users\JJH\OneDrive - Poyner Spruill\Documents\py\apibe\Venv\Lib\site-packages\django\core\handlers\exception.py", line 55, in inner
    response = get_response(request)
  File "C:\Users\JJH\OneDrive - Poyner Spruill\Documents\py\apibe\Venv\Lib\site-packages\django\core\handlers\base.py", line 197, in _get_response
    response = wrapped_callback(request, *callback_args, **callback_kwargs)
  File "C:\Users\JJH\OneDrive - Poyner Spruill\Documents\py\apibe\api\user_system\views.py", line 68, in redirect_auth
    result["preferred_username"]
    ~~~~~~^^^^^^^^^^^^^^^^^^^^^^
KeyError: 'preferred_username'
2024-10-19 23:35:57,597 [INFO]: C:\Users\JJH\OneDrive - Poyner Spruill\Documents\py\apibe\api\user_system\views.py changed, reloading.
2024-10-19 23:36:02,052 [ERROR]: Internal Server Error: /api/auth/getAToken
Traceback (most recent call last):
  File "C:\Users\JJH\OneDrive - Poyner Spruill\Documents\py\apibe\Venv\Lib\site-packages\django\core\handlers\exception.py", line 55, in inner
    response = get_response(request)
  File "C:\Users\JJH\OneDrive - Poyner Spruill\Documents\py\apibe\Venv\Lib\site-packages\django\core\handlers\base.py", line 197, in _get_response
    response = wrapped_callback(request, *callback_args, **callback_kwargs)
  File "C:\Users\JJH\OneDrive - Poyner Spruill\Documents\py\apibe\api\user_system\views.py", line 68, in redirect_auth
    result["id_token_claims"]["preferred_username"]
    ~~~~~~^^^^^^^^^^^^^^^^^^^
KeyError: 'id_token_claims'
2024-10-19 23:36:07,822 [ERROR]: Internal Server Error: /api/auth/getAToken
Traceback (most recent call last):
  File "C:\Users\JJH\OneDrive - Poyner Spruill\Documents\py\apibe\Venv\Lib\site-packages\django\core\handlers\exception.py", line 55, in inner
    response = get_response(request)
  File "C:\Users\JJH\OneDrive - Poyner Spruill\Documents\py\apibe\Venv\Lib\site-packages\django\core\handlers\base.py", line 197, in _get_response
    response = wrapped_callback(request, *callback_args, **callback_kwargs)
  File "C:\Users\JJH\OneDrive - Poyner Spruill\Documents\py\apibe\api\user_system\views.py", line 70, in redirect_auth
    print(len(hashed_token), hashed_token)
          ~~~^^^^^^^^^^^^^^
TypeError: object of type 'int' has no len()
2024-10-19 23:36:09,267 [ERROR]: Internal Server Error: /api/auth/getAToken
Traceback (most recent call last):
  File "C:\Users\JJH\OneDrive - Poyner Spruill\Documents\py\apibe\Venv\Lib\site-packages\django\core\handlers\exception.py", line 55, in inner
    response = get_response(request)
  File "C:\Users\JJH\OneDrive - Poyner Spruill\Documents\py\apibe\Venv\Lib\site-packages\django\core\handlers\base.py", line 197, in _get_response
    response = wrapped_callback(request, *callback_args, **callback_kwargs)
  File "C:\Users\JJH\OneDrive - Poyner Spruill\Documents\py\apibe\api\user_system\views.py", line 70, in redirect_auth
    print(len(hashed_token), hashed_token)
          ~~~^^^^^^^^^^^^^^
TypeError: object of type 'int' has no len()
2024-10-19 23:36:13,572 [ERROR]: Internal Server Error: /api/auth/getAToken
Traceback (most recent call last):
  File "C:\Users\JJH\OneDrive - Poyner Spruill\Documents\py\apibe\Venv\Lib\site-packages\django\core\handlers\exception.py", line 55, in inner
    response = get_response(request)
  File "C:\Users\JJH\OneDrive - Poyner Spruill\Documents\py\apibe\Venv\Lib\site-packages\django\core\handlers\base.py", line 197, in _get_response
    response = wrapped_callback(request, *callback_args, **callback_kwargs)
  File "C:\Users\JJH\OneDrive - Poyner Spruill\Documents\py\apibe\api\user_system\views.py", line 70, in redirect_auth
    print(len(hashed_token), hashed_token)
          ~~~^^^^^^^^^^^^^^
TypeError: object of type 'int' has no len()
2024-10-19 23:36:33,724 [INFO]: C:\Users\JJH\OneDrive - Poyner Spruill\Documents\py\apibe\api\user_system\views.py changed, reloading.
2024-10-19 23:36:39,164 [ERROR]: Internal Server Error: /api/auth/getAToken
Traceback (most recent call last):
  File "C:\Users\JJH\OneDrive - Poyner Spruill\Documents\py\apibe\Venv\Lib\site-packages\django\core\handlers\exception.py", line 55, in inner
    response = get_response(request)
  File "C:\Users\JJH\OneDrive - Poyner Spruill\Documents\py\apibe\Venv\Lib\site-packages\django\core\handlers\base.py", line 197, in _get_response
    response = wrapped_callback(request, *callback_args, **callback_kwargs)
  File "C:\Users\JJH\OneDrive - Poyner Spruill\Documents\py\apibe\api\user_system\views.py", line 68, in redirect_auth
    result["id_token_claims"]["preferred_username"]
    ~~~~~~^^^^^^^^^^^^^^^^^^^
KeyError: 'id_token_claims'
2024-10-19 23:42:56,999 [INFO]: C:\Users\JJH\OneDrive - Poyner Spruill\Documents\py\apibe\api\user_system\models.py changed, reloading.
2024-10-19 23:51:14,515 [INFO]: C:\Users\JJH\OneDrive - Poyner Spruill\Documents\py\apibe\api\user_system\views.py changed, reloading.
2024-10-19 23:59:00,313 [INFO]: C:\Users\JJH\OneDrive - Poyner Spruill\Documents\py\apibe\api\user_system\views.py changed, reloading.
2024-10-20 00:02:57,273 [INFO]: C:\Users\JJH\OneDrive - Poyner Spruill\Documents\py\apibe\api\user_system\views.py changed, reloading.
2024-10-20 00:03:31,017 [INFO]: C:\Users\JJH\OneDrive - Poyner Spruill\Documents\py\apibe\api\user_system\views.py changed, reloading.
2024-10-20 00:07:46,899 [INFO]: C:\Users\JJH\OneDrive - Poyner Spruill\Documents\py\apibe\api\user_system\models.py changed, reloading.
2024-10-20 00:08:09,552 [INFO]: C:\Users\JJH\OneDrive - Poyner Spruill\Documents\py\apibe\api\user_system\views.py changed, reloading.
2024-10-20 00:08:21,809 [INFO]: C:\Users\JJH\OneDrive - Poyner Spruill\Documents\py\apibe\api\user_system\models.py changed, reloading.
2024-10-20 00:09:55,633 [INFO]: C:\Users\JJH\OneDrive - Poyner Spruill\Documents\py\apibe\api\user_system\views.py changed, reloading.
2024-10-20 00:14:36,498 [INFO]: C:\Users\JJH\OneDrive - Poyner Spruill\Documents\py\apibe\api\user_system\views.py changed, reloading.
2024-10-20 00:16:07,940 [INFO]: C:\Users\JJH\OneDrive - Poyner Spruill\Documents\py\apibe\api\user_system\views.py changed, reloading.
2024-10-20 00:16:52,032 [INFO]: C:\Users\JJH\OneDrive - Poyner Spruill\Documents\py\apibe\api\user_system\views.py changed, reloading.
2024-10-20 00:17:43,495 [INFO]: C:\Users\JJH\OneDrive - Poyner Spruill\Documents\py\apibe\api\user_system\views.py changed, reloading.
2024-10-20 00:24:58,648 [INFO]: C:\Users\JJH\OneDrive - Poyner Spruill\Documents\py\apibe\api\user_system\views.py changed, reloading.
2024-10-20 00:28:39,585 [INFO]: C:\Users\JJH\OneDrive - Poyner Spruill\Documents\py\apibe\api\user_system\views.py changed, reloading.
2024-10-20 00:28:56,946 [INFO]: C:\Users\JJH\OneDrive - Poyner Spruill\Documents\py\apibe\api\user_system\views.py changed, reloading.
2024-10-20 00:29:02,658 [INFO]: C:\Users\JJH\OneDrive - Poyner Spruill\Documents\py\apibe\api\user_system\views.py changed, reloading.
2024-10-20 00:29:28,470 [INFO]: C:\Users\JJH\OneDrive - Poyner Spruill\Documents\py\apibe\api\user_system\views.py changed, reloading.
2024-10-20 00:30:12,878 [INFO]: C:\Users\JJH\OneDrive - Poyner Spruill\Documents\py\apibe\api\user_system\views.py changed, reloading.
2024-10-20 00:30:48,716 [INFO]: C:\Users\JJH\OneDrive - Poyner Spruill\Documents\py\apibe\api\user_system\views.py changed, reloading.
2024-10-20 00:31:47,219 [INFO]: C:\Users\JJH\OneDrive - Poyner Spruill\Documents\py\apibe\api\user_system\views.py changed, reloading.
2024-10-20 00:37:15,866 [INFO]: C:\Users\JJH\OneDrive - Poyner Spruill\Documents\py\apibe\api\user_system\models.py changed, reloading.
2024-10-20 00:39:49,302 [INFO]: C:\Users\JJH\OneDrive - Poyner Spruill\Documents\py\apibe\api\user_system\models.py changed, reloading.
2024-10-20 00:40:08,784 [INFO]: C:\Users\JJH\OneDrive - Poyner Spruill\Documents\py\apibe\api\user_system\views.py changed, reloading.
2024-10-20 00:46:00,148 [INFO]: C:\Users\JJH\OneDrive - Poyner Spruill\Documents\py\apibe\api\user_system\views.py changed, reloading.
2024-10-20 00:46:48,993 [INFO]: C:\Users\JJH\OneDrive - Poyner Spruill\Documents\py\apibe\api\user_system\views.py changed, reloading.
2024-10-20 00:53:01,299 [INFO]: C:\Users\JJH\OneDrive - Poyner Spruill\Documents\py\apibe\api\user_system\views.py changed, reloading.
2024-10-20 00:54:08,953 [INFO]: C:\Users\JJH\OneDrive - Poyner Spruill\Documents\py\apibe\api\user_system\views.py changed, reloading.
2024-10-20 00:56:13,362 [INFO]: C:\Users\JJH\OneDrive - Poyner Spruill\Documents\py\apibe\api\user_system\models.py changed, reloading.
2024-10-20 00:57:04,407 [ERROR]: Internal Server Error: /api/auth/getAToken
Traceback (most recent call last):
  File "C:\Users\JJH\OneDrive - Poyner Spruill\Documents\py\apibe\Venv\Lib\site-packages\django\core\handlers\exception.py", line 55, in inner
    response = get_response(request)
  File "C:\Users\JJH\OneDrive - Poyner Spruill\Documents\py\apibe\Venv\Lib\site-packages\django\core\handlers\base.py", line 197, in _get_response
    response = wrapped_callback(request, *callback_args, **callback_kwargs)
  File "C:\Users\JJH\OneDrive - Poyner Spruill\Documents\py\apibe\api\user_system\views.py", line 75, in redirect_auth
    encoded_access_token = encrypt_key.encrypt(f"{access_token}")
  File "C:\Users\JJH\OneDrive - Poyner Spruill\Documents\py\apibe\Venv\Lib\site-packages\cryptography\fernet.py", line 52, in encrypt
    return self.encrypt_at_time(data, int(time.time()))
           ~~~~~~~~~~~~~~~~~~~~^^^^^^^^^^^^^^^^^^^^^^^^
  File "C:\Users\JJH\OneDrive - Poyner Spruill\Documents\py\apibe\Venv\Lib\site-packages\cryptography\fernet.py", line 56, in encrypt_at_time
    return self._encrypt_from_parts(data, current_time, iv)
           ~~~~~~~~~~~~~~~~~~~~~~~~^^^^^^^^^^^^^^^^^^^^^^^^
  File "C:\Users\JJH\OneDrive - Poyner Spruill\Documents\py\apibe\Venv\Lib\site-packages\cryptography\fernet.py", line 61, in _encrypt_from_parts
    utils._check_bytes("data", data)
    ~~~~~~~~~~~~~~~~~~^^^^^^^^^^^^^^
  File "C:\Users\JJH\OneDrive - Poyner Spruill\Documents\py\apibe\Venv\Lib\site-packages\cryptography\utils.py", line 33, in _check_bytes
    raise TypeError(f"{name} must be bytes")
TypeError: data must be bytes
2024-10-20 00:57:13,828 [INFO]: C:\Users\JJH\OneDrive - Poyner Spruill\Documents\py\apibe\api\user_system\models.py changed, reloading.
2024-10-20 00:58:00,939 [INFO]: C:\Users\JJH\OneDrive - Poyner Spruill\Documents\py\apibe\api\user_system\views.py changed, reloading.
2024-10-20 00:58:07,847 [ERROR]: Internal Server Error: /api/auth/getAToken
Traceback (most recent call last):
  File "C:\Users\JJH\OneDrive - Poyner Spruill\Documents\py\apibe\Venv\Lib\site-packages\django\core\handlers\exception.py", line 55, in inner
    response = get_response(request)
  File "C:\Users\JJH\OneDrive - Poyner Spruill\Documents\py\apibe\Venv\Lib\site-packages\django\core\handlers\base.py", line 197, in _get_response
    response = wrapped_callback(request, *callback_args, **callback_kwargs)
  File "C:\Users\JJH\OneDrive - Poyner Spruill\Documents\py\apibe\api\user_system\views.py", line 76, in redirect_auth
    encoded_access_token = encrypt_key.encrypt(access_token)
  File "C:\Users\JJH\OneDrive - Poyner Spruill\Documents\py\apibe\Venv\Lib\site-packages\cryptography\fernet.py", line 52, in encrypt
    return self.encrypt_at_time(data, int(time.time()))
           ~~~~~~~~~~~~~~~~~~~~^^^^^^^^^^^^^^^^^^^^^^^^
  File "C:\Users\JJH\OneDrive - Poyner Spruill\Documents\py\apibe\Venv\Lib\site-packages\cryptography\fernet.py", line 56, in encrypt_at_time
    return self._encrypt_from_parts(data, current_time, iv)
           ~~~~~~~~~~~~~~~~~~~~~~~~^^^^^^^^^^^^^^^^^^^^^^^^
  File "C:\Users\JJH\OneDrive - Poyner Spruill\Documents\py\apibe\Venv\Lib\site-packages\cryptography\fernet.py", line 61, in _encrypt_from_parts
    utils._check_bytes("data", data)
    ~~~~~~~~~~~~~~~~~~^^^^^^^^^^^^^^
  File "C:\Users\JJH\OneDrive - Poyner Spruill\Documents\py\apibe\Venv\Lib\site-packages\cryptography\utils.py", line 33, in _check_bytes
    raise TypeError(f"{name} must be bytes")
TypeError: data must be bytes
2024-10-20 00:59:01,778 [INFO]: C:\Users\JJH\OneDrive - Poyner Spruill\Documents\py\apibe\api\user_system\views.py changed, reloading.
2024-10-20 00:59:11,021 [ERROR]: Internal Server Error: /api/auth/getAToken
Traceback (most recent call last):
  File "C:\Users\JJH\OneDrive - Poyner Spruill\Documents\py\apibe\Venv\Lib\site-packages\django\db\backends\utils.py", line 105, in _execute
    return self.cursor.execute(sql, params)
           ~~~~~~~~~~~~~~~~~~~^^^^^^^^^^^^^
  File "C:\Users\JJH\OneDrive - Poyner Spruill\Documents\py\apibe\Venv\Lib\site-packages\django\db\backends\sqlite3\base.py", line 354, in execute
    return super().execute(query, params)
           ~~~~~~~~~~~~~~~^^^^^^^^^^^^^^^
sqlite3.IntegrityError: UNIQUE constraint failed: auth_user.username

The above exception was the direct cause of the following exception:

Traceback (most recent call last):
  File "C:\Users\JJH\OneDrive - Poyner Spruill\Documents\py\apibe\Venv\Lib\site-packages\django\core\handlers\exception.py", line 55, in inner
    response = get_response(request)
  File "C:\Users\JJH\OneDrive - Poyner Spruill\Documents\py\apibe\Venv\Lib\site-packages\django\core\handlers\base.py", line 197, in _get_response
    response = wrapped_callback(request, *callback_args, **callback_kwargs)
  File "C:\Users\JJH\OneDrive - Poyner Spruill\Documents\py\apibe\api\user_system\views.py", line 101, in redirect_auth
    valid_user, created = User.objects.create(username=username)
                          ~~~~~~~~~~~~~~~~~~~^^^^^^^^^^^^^^^^^^^
  File "C:\Users\JJH\OneDrive - Poyner Spruill\Documents\py\apibe\Venv\Lib\site-packages\django\db\models\manager.py", line 87, in manager_method
    return getattr(self.get_queryset(), name)(*args, **kwargs)
           ~~~~~~~~~~~~~~~~~~~~~~~~~~~~~~~~~~^^^^^^^^^^^^^^^^^
  File "C:\Users\JJH\OneDrive - Poyner Spruill\Documents\py\apibe\Venv\Lib\site-packages\django\db\models\query.py", line 679, in create
    obj.save(force_insert=True, using=self.db)
    ~~~~~~~~^^^^^^^^^^^^^^^^^^^^^^^^^^^^^^^^^^
  File "C:\Users\JJH\OneDrive - Poyner Spruill\Documents\py\apibe\Venv\Lib\site-packages\django\contrib\auth\base_user.py", line 62, in save
    super().save(*args, **kwargs)
    ~~~~~~~~~~~~^^^^^^^^^^^^^^^^^
  File "C:\Users\JJH\OneDrive - Poyner Spruill\Documents\py\apibe\Venv\Lib\site-packages\django\db\models\base.py", line 891, in save
    self.save_base(
    ~~~~~~~~~~~~~~^
        using=using,
        ^^^^^^^^^^^^
    ...<2 lines>...
        update_fields=update_fields,
        ^^^^^^^^^^^^^^^^^^^^^^^^^^^^
    )
    ^
  File "C:\Users\JJH\OneDrive - Poyner Spruill\Documents\py\apibe\Venv\Lib\site-packages\django\db\models\base.py", line 997, in save_base
    updated = self._save_table(
        raw,
    ...<4 lines>...
        update_fields,
    )
  File "C:\Users\JJH\OneDrive - Poyner Spruill\Documents\py\apibe\Venv\Lib\site-packages\django\db\models\base.py", line 1160, in _save_table
    results = self._do_insert(
        cls._base_manager, using, fields, returning_fields, raw
    )
  File "C:\Users\JJH\OneDrive - Poyner Spruill\Documents\py\apibe\Venv\Lib\site-packages\django\db\models\base.py", line 1201, in _do_insert
    return manager._insert(
           ~~~~~~~~~~~~~~~^
        [self],
        ^^^^^^^
    ...<3 lines>...
        raw=raw,
        ^^^^^^^^
    )
    ^
  File "C:\Users\JJH\OneDrive - Poyner Spruill\Documents\py\apibe\Venv\Lib\site-packages\django\db\models\manager.py", line 87, in manager_method
    return getattr(self.get_queryset(), name)(*args, **kwargs)
           ~~~~~~~~~~~~~~~~~~~~~~~~~~~~~~~~~~^^^^^^^^^^^^^^^^^
  File "C:\Users\JJH\OneDrive - Poyner Spruill\Documents\py\apibe\Venv\Lib\site-packages\django\db\models\query.py", line 1847, in _insert
    return query.get_compiler(using=using).execute_sql(returning_fields)
           ~~~~~~~~~~~~~~~~~~~~~~~~~~~~~~~~~~~~~~~~~~~^^^^^^^^^^^^^^^^^^
  File "C:\Users\JJH\OneDrive - Poyner Spruill\Documents\py\apibe\Venv\Lib\site-packages\django\db\models\sql\compiler.py", line 1836, in execute_sql
    cursor.execute(sql, params)
    ~~~~~~~~~~~~~~^^^^^^^^^^^^^
  File "C:\Users\JJH\OneDrive - Poyner Spruill\Documents\py\apibe\Venv\Lib\site-packages\django\db\backends\utils.py", line 122, in execute
    return super().execute(sql, params)
           ~~~~~~~~~~~~~~~^^^^^^^^^^^^^
  File "C:\Users\JJH\OneDrive - Poyner Spruill\Documents\py\apibe\Venv\Lib\site-packages\django\db\backends\utils.py", line 79, in execute
    return self._execute_with_wrappers(
           ~~~~~~~~~~~~~~~~~~~~~~~~~~~^
        sql, params, many=False, executor=self._execute
        ^^^^^^^^^^^^^^^^^^^^^^^^^^^^^^^^^^^^^^^^^^^^^^^
    )
    ^
  File "C:\Users\JJH\OneDrive - Poyner Spruill\Documents\py\apibe\Venv\Lib\site-packages\django\db\backends\utils.py", line 92, in _execute_with_wrappers
    return executor(sql, params, many, context)
  File "C:\Users\JJH\OneDrive - Poyner Spruill\Documents\py\apibe\Venv\Lib\site-packages\django\db\backends\utils.py", line 100, in _execute
    with self.db.wrap_database_errors:
         ^^^^^^^^^^^^^^^^^^^^^^^^^^^^
  File "C:\Users\JJH\OneDrive - Poyner Spruill\Documents\py\apibe\Venv\Lib\site-packages\django\db\utils.py", line 91, in __exit__
    raise dj_exc_value.with_traceback(traceback) from exc_value
  File "C:\Users\JJH\OneDrive - Poyner Spruill\Documents\py\apibe\Venv\Lib\site-packages\django\db\backends\utils.py", line 105, in _execute
    return self.cursor.execute(sql, params)
           ~~~~~~~~~~~~~~~~~~~^^^^^^^^^^^^^
  File "C:\Users\JJH\OneDrive - Poyner Spruill\Documents\py\apibe\Venv\Lib\site-packages\django\db\backends\sqlite3\base.py", line 354, in execute
    return super().execute(query, params)
           ~~~~~~~~~~~~~~~^^^^^^^^^^^^^^^
django.db.utils.IntegrityError: UNIQUE constraint failed: auth_user.username
2024-10-20 01:02:41,748 [INFO]: C:\Users\JJH\OneDrive - Poyner Spruill\Documents\py\apibe\api\user_system\views.py changed, reloading.
2024-10-20 01:02:51,489 [ERROR]: Internal Server Error: /api/auth/validate_access
Traceback (most recent call last):
  File "C:\Users\JJH\OneDrive - Poyner Spruill\Documents\py\apibe\Venv\Lib\site-packages\django\core\handlers\exception.py", line 55, in inner
    response = get_response(request)
  File "C:\Users\JJH\OneDrive - Poyner Spruill\Documents\py\apibe\Venv\Lib\site-packages\django\core\handlers\base.py", line 220, in _get_response
    response = response.render()
  File "C:\Users\JJH\OneDrive - Poyner Spruill\Documents\py\apibe\Venv\Lib\site-packages\django\template\response.py", line 114, in render
    self.content = self.rendered_content
                   ^^^^^^^^^^^^^^^^^^^^^
  File "C:\Users\JJH\OneDrive - Poyner Spruill\Documents\py\apibe\Venv\Lib\site-packages\rest_framework\response.py", line 74, in rendered_content
    ret = renderer.render(self.data, accepted_media_type, context)
  File "C:\Users\JJH\OneDrive - Poyner Spruill\Documents\py\apibe\Venv\Lib\site-packages\rest_framework\renderers.py", line 100, in render
    ret = json.dumps(
        data, cls=self.encoder_class,
        indent=indent, ensure_ascii=self.ensure_ascii,
        allow_nan=not self.strict, separators=separators
    )
  File "C:\Users\JJH\OneDrive - Poyner Spruill\Documents\py\apibe\Venv\Lib\site-packages\rest_framework\utils\json.py", line 25, in dumps
    return json.dumps(*args, **kwargs)
           ~~~~~~~~~~^^^^^^^^^^^^^^^^^
  File "C:\Users\JJH\AppData\Local\Programs\Python\Python313\Lib\json\__init__.py", line 238, in dumps
    **kw).encode(obj)
          ~~~~~~^^^^^
  File "C:\Users\JJH\AppData\Local\Programs\Python\Python313\Lib\json\encoder.py", line 200, in encode
    chunks = self.iterencode(o, _one_shot=True)
  File "C:\Users\JJH\AppData\Local\Programs\Python\Python313\Lib\json\encoder.py", line 261, in iterencode
    return _iterencode(o, 0)
  File "C:\Users\JJH\OneDrive - Poyner Spruill\Documents\py\apibe\Venv\Lib\site-packages\rest_framework\utils\encoders.py", line 67, in default
    return super().default(obj)
           ~~~~~~~~~~~~~~~^^^^^
  File "C:\Users\JJH\AppData\Local\Programs\Python\Python313\Lib\json\encoder.py", line 180, in default
    raise TypeError(f'Object of type {o.__class__.__name__} '
                    f'is not JSON serializable')
TypeError: Object of type DoesNotExist is not JSON serializable
2024-10-20 01:06:36,594 [ERROR]: Internal Server Error: /api/auth/validation
Traceback (most recent call last):
  File "C:\Users\JJH\OneDrive - Poyner Spruill\Documents\py\apibe\Venv\Lib\site-packages\django\core\handlers\exception.py", line 55, in inner
    response = get_response(request)
  File "C:\Users\JJH\OneDrive - Poyner Spruill\Documents\py\apibe\Venv\Lib\site-packages\django\core\handlers\base.py", line 197, in _get_response
    response = wrapped_callback(request, *callback_args, **callback_kwargs)
  File "C:\Users\JJH\OneDrive - Poyner Spruill\Documents\py\apibe\Venv\Lib\site-packages\django\views\decorators\csrf.py", line 65, in _view_wrapper
    return view_func(request, *args, **kwargs)
  File "C:\Users\JJH\OneDrive - Poyner Spruill\Documents\py\apibe\Venv\Lib\site-packages\django\views\generic\base.py", line 104, in view
    return self.dispatch(request, *args, **kwargs)
           ~~~~~~~~~~~~~^^^^^^^^^^^^^^^^^^^^^^^^^^
  File "C:\Users\JJH\OneDrive - Poyner Spruill\Documents\py\apibe\Venv\Lib\site-packages\rest_framework\views.py", line 509, in dispatch
    response = self.handle_exception(exc)
  File "C:\Users\JJH\OneDrive - Poyner Spruill\Documents\py\apibe\Venv\Lib\site-packages\rest_framework\views.py", line 469, in handle_exception
    self.raise_uncaught_exception(exc)
    ~~~~~~~~~~~~~~~~~~~~~~~~~~~~~^^^^^
  File "C:\Users\JJH\OneDrive - Poyner Spruill\Documents\py\apibe\Venv\Lib\site-packages\rest_framework\views.py", line 480, in raise_uncaught_exception
    raise exc
  File "C:\Users\JJH\OneDrive - Poyner Spruill\Documents\py\apibe\Venv\Lib\site-packages\rest_framework\views.py", line 506, in dispatch
    response = handler(request, *args, **kwargs)
  File "C:\Users\JJH\OneDrive - Poyner Spruill\Documents\py\apibe\Venv\Lib\site-packages\rest_framework\decorators.py", line 50, in handler
    return func(*args, **kwargs)
  File "C:\Users\JJH\OneDrive - Poyner Spruill\Documents\py\apibe\api\user_system\views.py", line 144, in user_validation
    token = auth_header.split(" ")[1]
            ~~~~~~~~~~~~~~~~~~~~~~^^^
IndexError: list index out of range
2024-10-20 01:06:59,514 [ERROR]: Internal Server Error: /api/auth/validation
Traceback (most recent call last):
  File "C:\Users\JJH\OneDrive - Poyner Spruill\Documents\py\apibe\Venv\Lib\site-packages\django\core\handlers\exception.py", line 55, in inner
    response = get_response(request)
  File "C:\Users\JJH\OneDrive - Poyner Spruill\Documents\py\apibe\Venv\Lib\site-packages\django\core\handlers\base.py", line 197, in _get_response
    response = wrapped_callback(request, *callback_args, **callback_kwargs)
  File "C:\Users\JJH\OneDrive - Poyner Spruill\Documents\py\apibe\Venv\Lib\site-packages\django\views\decorators\csrf.py", line 65, in _view_wrapper
    return view_func(request, *args, **kwargs)
  File "C:\Users\JJH\OneDrive - Poyner Spruill\Documents\py\apibe\Venv\Lib\site-packages\django\views\generic\base.py", line 104, in view
    return self.dispatch(request, *args, **kwargs)
           ~~~~~~~~~~~~~^^^^^^^^^^^^^^^^^^^^^^^^^^
  File "C:\Users\JJH\OneDrive - Poyner Spruill\Documents\py\apibe\Venv\Lib\site-packages\rest_framework\views.py", line 509, in dispatch
    response = self.handle_exception(exc)
  File "C:\Users\JJH\OneDrive - Poyner Spruill\Documents\py\apibe\Venv\Lib\site-packages\rest_framework\views.py", line 469, in handle_exception
    self.raise_uncaught_exception(exc)
    ~~~~~~~~~~~~~~~~~~~~~~~~~~~~~^^^^^
  File "C:\Users\JJH\OneDrive - Poyner Spruill\Documents\py\apibe\Venv\Lib\site-packages\rest_framework\views.py", line 480, in raise_uncaught_exception
    raise exc
  File "C:\Users\JJH\OneDrive - Poyner Spruill\Documents\py\apibe\Venv\Lib\site-packages\rest_framework\views.py", line 506, in dispatch
    response = handler(request, *args, **kwargs)
  File "C:\Users\JJH\OneDrive - Poyner Spruill\Documents\py\apibe\Venv\Lib\site-packages\rest_framework\decorators.py", line 50, in handler
    return func(*args, **kwargs)
  File "C:\Users\JJH\OneDrive - Poyner Spruill\Documents\py\apibe\api\user_system\views.py", line 144, in user_validation
    token = auth_header.split(" ")[1]
            ~~~~~~~~~~~~~~~~~~~~~~^^^
IndexError: list index out of range
2024-10-20 01:07:50,028 [INFO]: C:\Users\JJH\OneDrive - Poyner Spruill\Documents\py\apibe\api\user_system\views.py changed, reloading.
2024-10-20 01:07:59,285 [ERROR]: Internal Server Error: /api/auth/validation
Traceback (most recent call last):
  File "C:\Users\JJH\OneDrive - Poyner Spruill\Documents\py\apibe\Venv\Lib\site-packages\django\core\handlers\exception.py", line 55, in inner
    response = get_response(request)
  File "C:\Users\JJH\OneDrive - Poyner Spruill\Documents\py\apibe\Venv\Lib\site-packages\django\core\handlers\base.py", line 197, in _get_response
    response = wrapped_callback(request, *callback_args, **callback_kwargs)
  File "C:\Users\JJH\OneDrive - Poyner Spruill\Documents\py\apibe\Venv\Lib\site-packages\django\views\decorators\csrf.py", line 65, in _view_wrapper
    return view_func(request, *args, **kwargs)
  File "C:\Users\JJH\OneDrive - Poyner Spruill\Documents\py\apibe\Venv\Lib\site-packages\django\views\generic\base.py", line 104, in view
    return self.dispatch(request, *args, **kwargs)
           ~~~~~~~~~~~~~^^^^^^^^^^^^^^^^^^^^^^^^^^
  File "C:\Users\JJH\OneDrive - Poyner Spruill\Documents\py\apibe\Venv\Lib\site-packages\rest_framework\views.py", line 509, in dispatch
    response = self.handle_exception(exc)
  File "C:\Users\JJH\OneDrive - Poyner Spruill\Documents\py\apibe\Venv\Lib\site-packages\rest_framework\views.py", line 469, in handle_exception
    self.raise_uncaught_exception(exc)
    ~~~~~~~~~~~~~~~~~~~~~~~~~~~~~^^^^^
  File "C:\Users\JJH\OneDrive - Poyner Spruill\Documents\py\apibe\Venv\Lib\site-packages\rest_framework\views.py", line 480, in raise_uncaught_exception
    raise exc
  File "C:\Users\JJH\OneDrive - Poyner Spruill\Documents\py\apibe\Venv\Lib\site-packages\rest_framework\views.py", line 506, in dispatch
    response = handler(request, *args, **kwargs)
  File "C:\Users\JJH\OneDrive - Poyner Spruill\Documents\py\apibe\Venv\Lib\site-packages\rest_framework\decorators.py", line 50, in handler
    return func(*args, **kwargs)
  File "C:\Users\JJH\OneDrive - Poyner Spruill\Documents\py\apibe\api\user_system\views.py", line 146, in user_validation
    linkage = MsAuthLink.objects.get(user=validating_token)
  File "C:\Users\JJH\OneDrive - Poyner Spruill\Documents\py\apibe\Venv\Lib\site-packages\django\db\models\manager.py", line 87, in manager_method
    return getattr(self.get_queryset(), name)(*args, **kwargs)
           ~~~~~~~~~~~~~~~~~~~~~~~~~~~~~~~~~~^^^^^^^^^^^^^^^^^
  File "C:\Users\JJH\OneDrive - Poyner Spruill\Documents\py\apibe\Venv\Lib\site-packages\django\db\models\query.py", line 635, in get
    clone = self._chain() if self.query.combinator else self.filter(*args, **kwargs)
                                                        ~~~~~~~~~~~^^^^^^^^^^^^^^^^^
  File "C:\Users\JJH\OneDrive - Poyner Spruill\Documents\py\apibe\Venv\Lib\site-packages\django\db\models\query.py", line 1476, in filter
    return self._filter_or_exclude(False, args, kwargs)
           ~~~~~~~~~~~~~~~~~~~~~~~^^^^^^^^^^^^^^^^^^^^^
  File "C:\Users\JJH\OneDrive - Poyner Spruill\Documents\py\apibe\Venv\Lib\site-packages\django\db\models\query.py", line 1494, in _filter_or_exclude
    clone._filter_or_exclude_inplace(negate, args, kwargs)
    ~~~~~~~~~~~~~~~~~~~~~~~~~~~~~~~~^^^^^^^^^^^^^^^^^^^^^^
  File "C:\Users\JJH\OneDrive - Poyner Spruill\Documents\py\apibe\Venv\Lib\site-packages\django\db\models\query.py", line 1501, in _filter_or_exclude_inplace
    self._query.add_q(Q(*args, **kwargs))
    ~~~~~~~~~~~~~~~~~^^^^^^^^^^^^^^^^^^^^
  File "C:\Users\JJH\OneDrive - Poyner Spruill\Documents\py\apibe\Venv\Lib\site-packages\django\db\models\sql\query.py", line 1609, in add_q
    clause, _ = self._add_q(q_object, self.used_aliases)
                ~~~~~~~~~~~^^^^^^^^^^^^^^^^^^^^^^^^^^^^^
  File "C:\Users\JJH\OneDrive - Poyner Spruill\Documents\py\apibe\Venv\Lib\site-packages\django\db\models\sql\query.py", line 1641, in _add_q
    child_clause, needed_inner = self.build_filter(
                                 ~~~~~~~~~~~~~~~~~^
        child,
        ^^^^^^
    ...<7 lines>...
        update_join_types=update_join_types,
        ^^^^^^^^^^^^^^^^^^^^^^^^^^^^^^^^^^^^
    )
    ^
  File "C:\Users\JJH\OneDrive - Poyner Spruill\Documents\py\apibe\Venv\Lib\site-packages\django\db\models\sql\query.py", line 1528, in build_filter
    self.check_related_objects(join_info.final_field, value, join_info.opts)
    ~~~~~~~~~~~~~~~~~~~~~~~~~~^^^^^^^^^^^^^^^^^^^^^^^^^^^^^^^^^^^^^^^^^^^^^^
  File "C:\Users\JJH\OneDrive - Poyner Spruill\Documents\py\apibe\Venv\Lib\site-packages\django\db\models\sql\query.py", line 1342, in check_related_objects
    self.check_query_object_type(value, opts, field)
    ~~~~~~~~~~~~~~~~~~~~~~~~~~~~^^^^^^^^^^^^^^^^^^^^
  File "C:\Users\JJH\OneDrive - Poyner Spruill\Documents\py\apibe\Venv\Lib\site-packages\django\db\models\sql\query.py", line 1319, in check_query_object_type
    raise ValueError(
    ...<2 lines>...
    )
ValueError: Cannot query "632b59717355bf031c1e02240622cb4022b46fa1": Must be "User" instance.
2024-10-20 01:08:26,429 [INFO]: C:\Users\JJH\OneDrive - Poyner Spruill\Documents\py\apibe\api\user_system\views.py changed, reloading.
2024-10-20 01:08:33,774 [ERROR]: Internal Server Error: /api/auth/validation
Traceback (most recent call last):
  File "C:\Users\JJH\OneDrive - Poyner Spruill\Documents\py\apibe\Venv\Lib\site-packages\django\core\handlers\exception.py", line 55, in inner
    response = get_response(request)
  File "C:\Users\JJH\OneDrive - Poyner Spruill\Documents\py\apibe\Venv\Lib\site-packages\django\core\handlers\base.py", line 197, in _get_response
    response = wrapped_callback(request, *callback_args, **callback_kwargs)
  File "C:\Users\JJH\OneDrive - Poyner Spruill\Documents\py\apibe\Venv\Lib\site-packages\django\views\decorators\csrf.py", line 65, in _view_wrapper
    return view_func(request, *args, **kwargs)
  File "C:\Users\JJH\OneDrive - Poyner Spruill\Documents\py\apibe\Venv\Lib\site-packages\django\views\generic\base.py", line 104, in view
    return self.dispatch(request, *args, **kwargs)
           ~~~~~~~~~~~~~^^^^^^^^^^^^^^^^^^^^^^^^^^
  File "C:\Users\JJH\OneDrive - Poyner Spruill\Documents\py\apibe\Venv\Lib\site-packages\rest_framework\views.py", line 509, in dispatch
    response = self.handle_exception(exc)
  File "C:\Users\JJH\OneDrive - Poyner Spruill\Documents\py\apibe\Venv\Lib\site-packages\rest_framework\views.py", line 469, in handle_exception
    self.raise_uncaught_exception(exc)
    ~~~~~~~~~~~~~~~~~~~~~~~~~~~~~^^^^^
  File "C:\Users\JJH\OneDrive - Poyner Spruill\Documents\py\apibe\Venv\Lib\site-packages\rest_framework\views.py", line 480, in raise_uncaught_exception
    raise exc
  File "C:\Users\JJH\OneDrive - Poyner Spruill\Documents\py\apibe\Venv\Lib\site-packages\rest_framework\views.py", line 506, in dispatch
    response = handler(request, *args, **kwargs)
  File "C:\Users\JJH\OneDrive - Poyner Spruill\Documents\py\apibe\Venv\Lib\site-packages\rest_framework\decorators.py", line 50, in handler
    return func(*args, **kwargs)
  File "C:\Users\JJH\OneDrive - Poyner Spruill\Documents\py\apibe\api\user_system\views.py", line 151, in user_validation
    access_token = encrypt_key.decrypt(user_linked.key).decode('utf-8')
                                       ^^^^^^^^^^^^^^^
AttributeError: 'User' object has no attribute 'key'
2024-10-20 01:08:57,448 [INFO]: C:\Users\JJH\OneDrive - Poyner Spruill\Documents\py\apibe\api\user_system\views.py changed, reloading.
2024-10-20 01:09:09,922 [ERROR]: Internal Server Error: /api/auth/validation
Traceback (most recent call last):
  File "C:\Users\JJH\OneDrive - Poyner Spruill\Documents\py\apibe\Venv\Lib\site-packages\django\core\handlers\exception.py", line 55, in inner
    response = get_response(request)
  File "C:\Users\JJH\OneDrive - Poyner Spruill\Documents\py\apibe\Venv\Lib\site-packages\django\core\handlers\base.py", line 197, in _get_response
    response = wrapped_callback(request, *callback_args, **callback_kwargs)
  File "C:\Users\JJH\OneDrive - Poyner Spruill\Documents\py\apibe\Venv\Lib\site-packages\django\views\decorators\csrf.py", line 65, in _view_wrapper
    return view_func(request, *args, **kwargs)
  File "C:\Users\JJH\OneDrive - Poyner Spruill\Documents\py\apibe\Venv\Lib\site-packages\django\views\generic\base.py", line 104, in view
    return self.dispatch(request, *args, **kwargs)
           ~~~~~~~~~~~~~^^^^^^^^^^^^^^^^^^^^^^^^^^
  File "C:\Users\JJH\OneDrive - Poyner Spruill\Documents\py\apibe\Venv\Lib\site-packages\rest_framework\views.py", line 509, in dispatch
    response = self.handle_exception(exc)
  File "C:\Users\JJH\OneDrive - Poyner Spruill\Documents\py\apibe\Venv\Lib\site-packages\rest_framework\views.py", line 469, in handle_exception
    self.raise_uncaught_exception(exc)
    ~~~~~~~~~~~~~~~~~~~~~~~~~~~~~^^^^^
  File "C:\Users\JJH\OneDrive - Poyner Spruill\Documents\py\apibe\Venv\Lib\site-packages\rest_framework\views.py", line 480, in raise_uncaught_exception
    raise exc
  File "C:\Users\JJH\OneDrive - Poyner Spruill\Documents\py\apibe\Venv\Lib\site-packages\rest_framework\views.py", line 506, in dispatch
    response = handler(request, *args, **kwargs)
  File "C:\Users\JJH\OneDrive - Poyner Spruill\Documents\py\apibe\Venv\Lib\site-packages\rest_framework\decorators.py", line 50, in handler
    return func(*args, **kwargs)
  File "C:\Users\JJH\OneDrive - Poyner Spruill\Documents\py\apibe\api\user_system\views.py", line 151, in user_validation
    access_token = encrypt_key.decrypt(user_linked.key).decode('utf-8')
                   ~~~~~~~~~~~~~~~~~~~^^^^^^^^^^^^^^^^^
  File "C:\Users\JJH\OneDrive - Poyner Spruill\Documents\py\apibe\Venv\Lib\site-packages\cryptography\fernet.py", line 84, in decrypt
    timestamp, data = Fernet._get_unverified_token_data(token)
                      ~~~~~~~~~~~~~~~~~~~~~~~~~~~~~~~~~^^^^^^^
  File "C:\Users\JJH\OneDrive - Poyner Spruill\Documents\py\apibe\Venv\Lib\site-packages\cryptography\fernet.py", line 118, in _get_unverified_token_data
    raise InvalidToken
cryptography.fernet.InvalidToken
2024-10-20 01:10:00,840 [INFO]: C:\Users\JJH\OneDrive - Poyner Spruill\Documents\py\apibe\api\user_system\views.py changed, reloading.
2024-10-20 01:11:45,704 [INFO]: C:\Users\JJH\OneDrive - Poyner Spruill\Documents\py\apibe\api\user_system\views.py changed, reloading.
2024-10-20 01:11:53,590 [ERROR]: Internal Server Error: /api/auth/validation
Traceback (most recent call last):
  File "C:\Users\JJH\OneDrive - Poyner Spruill\Documents\py\apibe\Venv\Lib\site-packages\django\core\handlers\exception.py", line 55, in inner
    response = get_response(request)
  File "C:\Users\JJH\OneDrive - Poyner Spruill\Documents\py\apibe\Venv\Lib\site-packages\django\core\handlers\base.py", line 197, in _get_response
    response = wrapped_callback(request, *callback_args, **callback_kwargs)
  File "C:\Users\JJH\OneDrive - Poyner Spruill\Documents\py\apibe\Venv\Lib\site-packages\django\views\decorators\csrf.py", line 65, in _view_wrapper
    return view_func(request, *args, **kwargs)
  File "C:\Users\JJH\OneDrive - Poyner Spruill\Documents\py\apibe\Venv\Lib\site-packages\django\views\generic\base.py", line 104, in view
    return self.dispatch(request, *args, **kwargs)
           ~~~~~~~~~~~~~^^^^^^^^^^^^^^^^^^^^^^^^^^
  File "C:\Users\JJH\OneDrive - Poyner Spruill\Documents\py\apibe\Venv\Lib\site-packages\rest_framework\views.py", line 509, in dispatch
    response = self.handle_exception(exc)
  File "C:\Users\JJH\OneDrive - Poyner Spruill\Documents\py\apibe\Venv\Lib\site-packages\rest_framework\views.py", line 469, in handle_exception
    self.raise_uncaught_exception(exc)
    ~~~~~~~~~~~~~~~~~~~~~~~~~~~~~^^^^^
  File "C:\Users\JJH\OneDrive - Poyner Spruill\Documents\py\apibe\Venv\Lib\site-packages\rest_framework\views.py", line 480, in raise_uncaught_exception
    raise exc
  File "C:\Users\JJH\OneDrive - Poyner Spruill\Documents\py\apibe\Venv\Lib\site-packages\rest_framework\views.py", line 506, in dispatch
    response = handler(request, *args, **kwargs)
  File "C:\Users\JJH\OneDrive - Poyner Spruill\Documents\py\apibe\Venv\Lib\site-packages\rest_framework\decorators.py", line 50, in handler
    return func(*args, **kwargs)
  File "C:\Users\JJH\OneDrive - Poyner Spruill\Documents\py\apibe\api\user_system\views.py", line 151, in user_validation
    access_token = encrypt_key.decrypt(str(user_linked.key)).decode('utf-8')
                   ~~~~~~~~~~~~~~~~~~~^^^^^^^^^^^^^^^^^^^^^^
  File "C:\Users\JJH\OneDrive - Poyner Spruill\Documents\py\apibe\Venv\Lib\site-packages\cryptography\fernet.py", line 84, in decrypt
    timestamp, data = Fernet._get_unverified_token_data(token)
                      ~~~~~~~~~~~~~~~~~~~~~~~~~~~~~~~~~^^^^^^^
  File "C:\Users\JJH\OneDrive - Poyner Spruill\Documents\py\apibe\Venv\Lib\site-packages\cryptography\fernet.py", line 118, in _get_unverified_token_data
    raise InvalidToken
cryptography.fernet.InvalidToken
2024-10-20 01:17:18,807 [INFO]: C:\Users\JJH\OneDrive - Poyner Spruill\Documents\py\apibe\api\user_system\views.py changed, reloading.
2024-10-20 01:18:08,524 [ERROR]: Internal Server Error: /api/auth/validation
Traceback (most recent call last):
  File "C:\Users\JJH\OneDrive - Poyner Spruill\Documents\py\apibe\Venv\Lib\site-packages\django\core\handlers\exception.py", line 55, in inner
    response = get_response(request)
  File "C:\Users\JJH\OneDrive - Poyner Spruill\Documents\py\apibe\Venv\Lib\site-packages\django\core\handlers\base.py", line 197, in _get_response
    response = wrapped_callback(request, *callback_args, **callback_kwargs)
  File "C:\Users\JJH\OneDrive - Poyner Spruill\Documents\py\apibe\Venv\Lib\site-packages\django\views\decorators\csrf.py", line 65, in _view_wrapper
    return view_func(request, *args, **kwargs)
  File "C:\Users\JJH\OneDrive - Poyner Spruill\Documents\py\apibe\Venv\Lib\site-packages\django\views\generic\base.py", line 104, in view
    return self.dispatch(request, *args, **kwargs)
           ~~~~~~~~~~~~~^^^^^^^^^^^^^^^^^^^^^^^^^^
  File "C:\Users\JJH\OneDrive - Poyner Spruill\Documents\py\apibe\Venv\Lib\site-packages\rest_framework\views.py", line 509, in dispatch
    response = self.handle_exception(exc)
  File "C:\Users\JJH\OneDrive - Poyner Spruill\Documents\py\apibe\Venv\Lib\site-packages\rest_framework\views.py", line 469, in handle_exception
    self.raise_uncaught_exception(exc)
    ~~~~~~~~~~~~~~~~~~~~~~~~~~~~~^^^^^
  File "C:\Users\JJH\OneDrive - Poyner Spruill\Documents\py\apibe\Venv\Lib\site-packages\rest_framework\views.py", line 480, in raise_uncaught_exception
    raise exc
  File "C:\Users\JJH\OneDrive - Poyner Spruill\Documents\py\apibe\Venv\Lib\site-packages\rest_framework\views.py", line 506, in dispatch
    response = handler(request, *args, **kwargs)
  File "C:\Users\JJH\OneDrive - Poyner Spruill\Documents\py\apibe\Venv\Lib\site-packages\rest_framework\decorators.py", line 50, in handler
    return func(*args, **kwargs)
  File "C:\Users\JJH\OneDrive - Poyner Spruill\Documents\py\apibe\api\user_system\views.py", line 151, in user_validation
    access_token = encrypt_key.decrypt(str(user_linked.key)).decode('utf-8')
                   ~~~~~~~~~~~~~~~~~~~^^^^^^^^^^^^^^^^^^^^^^
  File "C:\Users\JJH\OneDrive - Poyner Spruill\Documents\py\apibe\Venv\Lib\site-packages\cryptography\fernet.py", line 84, in decrypt
    timestamp, data = Fernet._get_unverified_token_data(token)
                      ~~~~~~~~~~~~~~~~~~~~~~~~~~~~~~~~~^^^^^^^
  File "C:\Users\JJH\OneDrive - Poyner Spruill\Documents\py\apibe\Venv\Lib\site-packages\cryptography\fernet.py", line 118, in _get_unverified_token_data
    raise InvalidToken
cryptography.fernet.InvalidToken
2024-10-20 01:23:28,160 [INFO]: C:\Users\JJH\OneDrive - Poyner Spruill\Documents\py\apibe\api\user_system\views.py changed, reloading.
2024-10-20 01:23:54,261 [ERROR]: Internal Server Error: /api/auth/validation
Traceback (most recent call last):
  File "C:\Users\JJH\OneDrive - Poyner Spruill\Documents\py\apibe\Venv\Lib\site-packages\django\core\handlers\exception.py", line 55, in inner
    response = get_response(request)
  File "C:\Users\JJH\OneDrive - Poyner Spruill\Documents\py\apibe\Venv\Lib\site-packages\django\core\handlers\base.py", line 197, in _get_response
    response = wrapped_callback(request, *callback_args, **callback_kwargs)
  File "C:\Users\JJH\OneDrive - Poyner Spruill\Documents\py\apibe\Venv\Lib\site-packages\django\views\decorators\csrf.py", line 65, in _view_wrapper
    return view_func(request, *args, **kwargs)
  File "C:\Users\JJH\OneDrive - Poyner Spruill\Documents\py\apibe\Venv\Lib\site-packages\django\views\generic\base.py", line 104, in view
    return self.dispatch(request, *args, **kwargs)
           ~~~~~~~~~~~~~^^^^^^^^^^^^^^^^^^^^^^^^^^
  File "C:\Users\JJH\OneDrive - Poyner Spruill\Documents\py\apibe\Venv\Lib\site-packages\rest_framework\views.py", line 509, in dispatch
    response = self.handle_exception(exc)
  File "C:\Users\JJH\OneDrive - Poyner Spruill\Documents\py\apibe\Venv\Lib\site-packages\rest_framework\views.py", line 469, in handle_exception
    self.raise_uncaught_exception(exc)
    ~~~~~~~~~~~~~~~~~~~~~~~~~~~~~^^^^^
  File "C:\Users\JJH\OneDrive - Poyner Spruill\Documents\py\apibe\Venv\Lib\site-packages\rest_framework\views.py", line 480, in raise_uncaught_exception
    raise exc
  File "C:\Users\JJH\OneDrive - Poyner Spruill\Documents\py\apibe\Venv\Lib\site-packages\rest_framework\views.py", line 506, in dispatch
    response = handler(request, *args, **kwargs)
  File "C:\Users\JJH\OneDrive - Poyner Spruill\Documents\py\apibe\Venv\Lib\site-packages\rest_framework\decorators.py", line 50, in handler
    return func(*args, **kwargs)
  File "C:\Users\JJH\OneDrive - Poyner Spruill\Documents\py\apibe\api\user_system\views.py", line 151, in user_validation
    access_token = encrypt_key.decrypt(user_linked.key).decode('utf-8')
                   ~~~~~~~~~~~~~~~~~~~^^^^^^^^^^^^^^^^^
  File "C:\Users\JJH\OneDrive - Poyner Spruill\Documents\py\apibe\Venv\Lib\site-packages\cryptography\fernet.py", line 84, in decrypt
    timestamp, data = Fernet._get_unverified_token_data(token)
                      ~~~~~~~~~~~~~~~~~~~~~~~~~~~~~~~~~^^^^^^^
  File "C:\Users\JJH\OneDrive - Poyner Spruill\Documents\py\apibe\Venv\Lib\site-packages\cryptography\fernet.py", line 118, in _get_unverified_token_data
    raise InvalidToken
cryptography.fernet.InvalidToken
2024-10-20 01:25:08,305 [INFO]: C:\Users\JJH\OneDrive - Poyner Spruill\Documents\py\apibe\api\user_system\admin.py changed, reloading.
2024-10-20 01:31:25,553 [INFO]: C:\Users\JJH\OneDrive - Poyner Spruill\Documents\py\apibe\api\user_system\views.py changed, reloading.
2024-10-20 01:31:38,825 [INFO]: C:\Users\JJH\OneDrive - Poyner Spruill\Documents\py\apibe\api\user_system\views.py changed, reloading.
2024-10-20 01:32:08,006 [INFO]: C:\Users\JJH\OneDrive - Poyner Spruill\Documents\py\apibe\api\user_system\views.py changed, reloading.
2024-10-20 01:32:19,679 [ERROR]: Internal Server Error: /api/auth/validation
Traceback (most recent call last):
  File "C:\Users\JJH\OneDrive - Poyner Spruill\Documents\py\apibe\Venv\Lib\site-packages\django\core\handlers\exception.py", line 55, in inner
    response = get_response(request)
  File "C:\Users\JJH\OneDrive - Poyner Spruill\Documents\py\apibe\Venv\Lib\site-packages\django\core\handlers\base.py", line 197, in _get_response
    response = wrapped_callback(request, *callback_args, **callback_kwargs)
  File "C:\Users\JJH\OneDrive - Poyner Spruill\Documents\py\apibe\Venv\Lib\site-packages\django\views\decorators\csrf.py", line 65, in _view_wrapper
    return view_func(request, *args, **kwargs)
  File "C:\Users\JJH\OneDrive - Poyner Spruill\Documents\py\apibe\Venv\Lib\site-packages\django\views\generic\base.py", line 104, in view
    return self.dispatch(request, *args, **kwargs)
           ~~~~~~~~~~~~~^^^^^^^^^^^^^^^^^^^^^^^^^^
  File "C:\Users\JJH\OneDrive - Poyner Spruill\Documents\py\apibe\Venv\Lib\site-packages\rest_framework\views.py", line 509, in dispatch
    response = self.handle_exception(exc)
  File "C:\Users\JJH\OneDrive - Poyner Spruill\Documents\py\apibe\Venv\Lib\site-packages\rest_framework\views.py", line 469, in handle_exception
    self.raise_uncaught_exception(exc)
    ~~~~~~~~~~~~~~~~~~~~~~~~~~~~~^^^^^
  File "C:\Users\JJH\OneDrive - Poyner Spruill\Documents\py\apibe\Venv\Lib\site-packages\rest_framework\views.py", line 480, in raise_uncaught_exception
    raise exc
  File "C:\Users\JJH\OneDrive - Poyner Spruill\Documents\py\apibe\Venv\Lib\site-packages\rest_framework\views.py", line 506, in dispatch
    response = handler(request, *args, **kwargs)
  File "C:\Users\JJH\OneDrive - Poyner Spruill\Documents\py\apibe\Venv\Lib\site-packages\rest_framework\decorators.py", line 50, in handler
    return func(*args, **kwargs)
  File "C:\Users\JJH\OneDrive - Poyner Spruill\Documents\py\apibe\api\user_system\views.py", line 151, in user_validation
    access_token = encrypt_key.decrypt(linkage.key).decode('utf-8')
                   ~~~~~~~~~~~~~~~~~~~^^^^^^^^^^^^^
  File "C:\Users\JJH\OneDrive - Poyner Spruill\Documents\py\apibe\Venv\Lib\site-packages\cryptography\fernet.py", line 84, in decrypt
    timestamp, data = Fernet._get_unverified_token_data(token)
                      ~~~~~~~~~~~~~~~~~~~~~~~~~~~~~~~~~^^^^^^^
  File "C:\Users\JJH\OneDrive - Poyner Spruill\Documents\py\apibe\Venv\Lib\site-packages\cryptography\fernet.py", line 118, in _get_unverified_token_data
    raise InvalidToken
cryptography.fernet.InvalidToken
2024-10-20 01:32:51,475 [INFO]: C:\Users\JJH\OneDrive - Poyner Spruill\Documents\py\apibe\api\user_system\views.py changed, reloading.
2024-10-20 01:32:59,103 [ERROR]: Internal Server Error: /api/auth/validation
Traceback (most recent call last):
  File "C:\Users\JJH\OneDrive - Poyner Spruill\Documents\py\apibe\Venv\Lib\site-packages\django\core\handlers\exception.py", line 55, in inner
    response = get_response(request)
  File "C:\Users\JJH\OneDrive - Poyner Spruill\Documents\py\apibe\Venv\Lib\site-packages\django\core\handlers\base.py", line 197, in _get_response
    response = wrapped_callback(request, *callback_args, **callback_kwargs)
  File "C:\Users\JJH\OneDrive - Poyner Spruill\Documents\py\apibe\Venv\Lib\site-packages\django\views\decorators\csrf.py", line 65, in _view_wrapper
    return view_func(request, *args, **kwargs)
  File "C:\Users\JJH\OneDrive - Poyner Spruill\Documents\py\apibe\Venv\Lib\site-packages\django\views\generic\base.py", line 104, in view
    return self.dispatch(request, *args, **kwargs)
           ~~~~~~~~~~~~~^^^^^^^^^^^^^^^^^^^^^^^^^^
  File "C:\Users\JJH\OneDrive - Poyner Spruill\Documents\py\apibe\Venv\Lib\site-packages\rest_framework\views.py", line 509, in dispatch
    response = self.handle_exception(exc)
  File "C:\Users\JJH\OneDrive - Poyner Spruill\Documents\py\apibe\Venv\Lib\site-packages\rest_framework\views.py", line 469, in handle_exception
    self.raise_uncaught_exception(exc)
    ~~~~~~~~~~~~~~~~~~~~~~~~~~~~~^^^^^
  File "C:\Users\JJH\OneDrive - Poyner Spruill\Documents\py\apibe\Venv\Lib\site-packages\rest_framework\views.py", line 480, in raise_uncaught_exception
    raise exc
  File "C:\Users\JJH\OneDrive - Poyner Spruill\Documents\py\apibe\Venv\Lib\site-packages\rest_framework\views.py", line 506, in dispatch
    response = handler(request, *args, **kwargs)
  File "C:\Users\JJH\OneDrive - Poyner Spruill\Documents\py\apibe\Venv\Lib\site-packages\rest_framework\decorators.py", line 50, in handler
    return func(*args, **kwargs)
  File "C:\Users\JJH\OneDrive - Poyner Spruill\Documents\py\apibe\api\user_system\views.py", line 152, in user_validation
    access_token = encrypt_key.decrypt(linkage.key).decode('utf-8')
                   ~~~~~~~~~~~~~~~~~~~^^^^^^^^^^^^^
  File "C:\Users\JJH\OneDrive - Poyner Spruill\Documents\py\apibe\Venv\Lib\site-packages\cryptography\fernet.py", line 84, in decrypt
    timestamp, data = Fernet._get_unverified_token_data(token)
                      ~~~~~~~~~~~~~~~~~~~~~~~~~~~~~~~~~^^^^^^^
  File "C:\Users\JJH\OneDrive - Poyner Spruill\Documents\py\apibe\Venv\Lib\site-packages\cryptography\fernet.py", line 118, in _get_unverified_token_data
    raise InvalidToken
cryptography.fernet.InvalidToken
2024-10-20 01:36:37,504 [INFO]: C:\Users\JJH\OneDrive - Poyner Spruill\Documents\py\apibe\api\user_system\views.py changed, reloading.
2024-10-20 01:38:40,723 [INFO]: C:\Users\JJH\OneDrive - Poyner Spruill\Documents\py\apibe\api\user_system\views.py changed, reloading.
2024-10-20 01:39:01,380 [ERROR]: Internal Server Error: /api/auth/validation
Traceback (most recent call last):
  File "C:\Users\JJH\OneDrive - Poyner Spruill\Documents\py\apibe\Venv\Lib\site-packages\django\core\handlers\exception.py", line 55, in inner
    response = get_response(request)
  File "C:\Users\JJH\OneDrive - Poyner Spruill\Documents\py\apibe\Venv\Lib\site-packages\django\core\handlers\base.py", line 197, in _get_response
    response = wrapped_callback(request, *callback_args, **callback_kwargs)
  File "C:\Users\JJH\OneDrive - Poyner Spruill\Documents\py\apibe\Venv\Lib\site-packages\django\views\decorators\csrf.py", line 65, in _view_wrapper
    return view_func(request, *args, **kwargs)
  File "C:\Users\JJH\OneDrive - Poyner Spruill\Documents\py\apibe\Venv\Lib\site-packages\django\views\generic\base.py", line 104, in view
    return self.dispatch(request, *args, **kwargs)
           ~~~~~~~~~~~~~^^^^^^^^^^^^^^^^^^^^^^^^^^
  File "C:\Users\JJH\OneDrive - Poyner Spruill\Documents\py\apibe\Venv\Lib\site-packages\rest_framework\views.py", line 509, in dispatch
    response = self.handle_exception(exc)
  File "C:\Users\JJH\OneDrive - Poyner Spruill\Documents\py\apibe\Venv\Lib\site-packages\rest_framework\views.py", line 469, in handle_exception
    self.raise_uncaught_exception(exc)
    ~~~~~~~~~~~~~~~~~~~~~~~~~~~~~^^^^^
  File "C:\Users\JJH\OneDrive - Poyner Spruill\Documents\py\apibe\Venv\Lib\site-packages\rest_framework\views.py", line 480, in raise_uncaught_exception
    raise exc
  File "C:\Users\JJH\OneDrive - Poyner Spruill\Documents\py\apibe\Venv\Lib\site-packages\rest_framework\views.py", line 506, in dispatch
    response = handler(request, *args, **kwargs)
  File "C:\Users\JJH\OneDrive - Poyner Spruill\Documents\py\apibe\Venv\Lib\site-packages\rest_framework\decorators.py", line 50, in handler
    return func(*args, **kwargs)
  File "C:\Users\JJH\OneDrive - Poyner Spruill\Documents\py\apibe\api\user_system\views.py", line 152, in user_validation
    access_token = encrypt_key.decrypt(linkage.key).decode('utf-8')
                   ~~~~~~~~~~~~~~~~~~~^^^^^^^^^^^^^
  File "C:\Users\JJH\OneDrive - Poyner Spruill\Documents\py\apibe\Venv\Lib\site-packages\cryptography\fernet.py", line 84, in decrypt
    timestamp, data = Fernet._get_unverified_token_data(token)
                      ~~~~~~~~~~~~~~~~~~~~~~~~~~~~~~~~~^^^^^^^
  File "C:\Users\JJH\OneDrive - Poyner Spruill\Documents\py\apibe\Venv\Lib\site-packages\cryptography\fernet.py", line 118, in _get_unverified_token_data
    raise InvalidToken
cryptography.fernet.InvalidToken
2024-10-20 01:39:14,211 [ERROR]: Internal Server Error: /api/auth/validation
Traceback (most recent call last):
  File "C:\Users\JJH\OneDrive - Poyner Spruill\Documents\py\apibe\Venv\Lib\site-packages\django\core\handlers\exception.py", line 55, in inner
    response = get_response(request)
  File "C:\Users\JJH\OneDrive - Poyner Spruill\Documents\py\apibe\Venv\Lib\site-packages\django\core\handlers\base.py", line 197, in _get_response
    response = wrapped_callback(request, *callback_args, **callback_kwargs)
  File "C:\Users\JJH\OneDrive - Poyner Spruill\Documents\py\apibe\Venv\Lib\site-packages\django\views\decorators\csrf.py", line 65, in _view_wrapper
    return view_func(request, *args, **kwargs)
  File "C:\Users\JJH\OneDrive - Poyner Spruill\Documents\py\apibe\Venv\Lib\site-packages\django\views\generic\base.py", line 104, in view
    return self.dispatch(request, *args, **kwargs)
           ~~~~~~~~~~~~~^^^^^^^^^^^^^^^^^^^^^^^^^^
  File "C:\Users\JJH\OneDrive - Poyner Spruill\Documents\py\apibe\Venv\Lib\site-packages\rest_framework\views.py", line 509, in dispatch
    response = self.handle_exception(exc)
  File "C:\Users\JJH\OneDrive - Poyner Spruill\Documents\py\apibe\Venv\Lib\site-packages\rest_framework\views.py", line 469, in handle_exception
    self.raise_uncaught_exception(exc)
    ~~~~~~~~~~~~~~~~~~~~~~~~~~~~~^^^^^
  File "C:\Users\JJH\OneDrive - Poyner Spruill\Documents\py\apibe\Venv\Lib\site-packages\rest_framework\views.py", line 480, in raise_uncaught_exception
    raise exc
  File "C:\Users\JJH\OneDrive - Poyner Spruill\Documents\py\apibe\Venv\Lib\site-packages\rest_framework\views.py", line 506, in dispatch
    response = handler(request, *args, **kwargs)
  File "C:\Users\JJH\OneDrive - Poyner Spruill\Documents\py\apibe\Venv\Lib\site-packages\rest_framework\decorators.py", line 50, in handler
    return func(*args, **kwargs)
  File "C:\Users\JJH\OneDrive - Poyner Spruill\Documents\py\apibe\api\user_system\views.py", line 152, in user_validation
    access_token = encrypt_key.decrypt(linkage.key).decode('utf-8')
                   ~~~~~~~~~~~~~~~~~~~^^^^^^^^^^^^^
  File "C:\Users\JJH\OneDrive - Poyner Spruill\Documents\py\apibe\Venv\Lib\site-packages\cryptography\fernet.py", line 84, in decrypt
    timestamp, data = Fernet._get_unverified_token_data(token)
                      ~~~~~~~~~~~~~~~~~~~~~~~~~~~~~~~~~^^^^^^^
  File "C:\Users\JJH\OneDrive - Poyner Spruill\Documents\py\apibe\Venv\Lib\site-packages\cryptography\fernet.py", line 118, in _get_unverified_token_data
    raise InvalidToken
cryptography.fernet.InvalidToken
2024-10-20 01:40:45,678 [INFO]: C:\Users\JJH\OneDrive - Poyner Spruill\Documents\py\apibe\api\user_system\views.py changed, reloading.
2024-10-20 01:42:02,066 [INFO]: C:\Users\JJH\OneDrive - Poyner Spruill\Documents\py\apibe\api\user_system\views.py changed, reloading.
2024-10-20 01:42:08,878 [INFO]: C:\Users\JJH\OneDrive - Poyner Spruill\Documents\py\apibe\api\user_system\views.py changed, reloading.
2024-10-20 01:42:49,822 [INFO]: C:\Users\JJH\OneDrive - Poyner Spruill\Documents\py\apibe\api\user_system\views.py changed, reloading.
2024-10-20 01:43:02,258 [ERROR]: Internal Server Error: /api/auth/validation
Traceback (most recent call last):
  File "C:\Users\JJH\OneDrive - Poyner Spruill\Documents\py\apibe\Venv\Lib\site-packages\django\core\handlers\exception.py", line 55, in inner
    response = get_response(request)
  File "C:\Users\JJH\OneDrive - Poyner Spruill\Documents\py\apibe\Venv\Lib\site-packages\django\core\handlers\base.py", line 197, in _get_response
    response = wrapped_callback(request, *callback_args, **callback_kwargs)
  File "C:\Users\JJH\OneDrive - Poyner Spruill\Documents\py\apibe\Venv\Lib\site-packages\django\views\decorators\csrf.py", line 65, in _view_wrapper
    return view_func(request, *args, **kwargs)
  File "C:\Users\JJH\OneDrive - Poyner Spruill\Documents\py\apibe\Venv\Lib\site-packages\django\views\generic\base.py", line 104, in view
    return self.dispatch(request, *args, **kwargs)
           ~~~~~~~~~~~~~^^^^^^^^^^^^^^^^^^^^^^^^^^
  File "C:\Users\JJH\OneDrive - Poyner Spruill\Documents\py\apibe\Venv\Lib\site-packages\rest_framework\views.py", line 509, in dispatch
    response = self.handle_exception(exc)
  File "C:\Users\JJH\OneDrive - Poyner Spruill\Documents\py\apibe\Venv\Lib\site-packages\rest_framework\views.py", line 469, in handle_exception
    self.raise_uncaught_exception(exc)
    ~~~~~~~~~~~~~~~~~~~~~~~~~~~~~^^^^^
  File "C:\Users\JJH\OneDrive - Poyner Spruill\Documents\py\apibe\Venv\Lib\site-packages\rest_framework\views.py", line 480, in raise_uncaught_exception
    raise exc
  File "C:\Users\JJH\OneDrive - Poyner Spruill\Documents\py\apibe\Venv\Lib\site-packages\rest_framework\views.py", line 506, in dispatch
    response = handler(request, *args, **kwargs)
  File "C:\Users\JJH\OneDrive - Poyner Spruill\Documents\py\apibe\Venv\Lib\site-packages\rest_framework\decorators.py", line 50, in handler
    return func(*args, **kwargs)
  File "C:\Users\JJH\OneDrive - Poyner Spruill\Documents\py\apibe\api\user_system\views.py", line 151, in user_validation
    access_token = encrypt_key.decrypt(linkage.key).decode('utf-8')
                   ~~~~~~~~~~~~~~~~~~~^^^^^^^^^^^^^
  File "C:\Users\JJH\OneDrive - Poyner Spruill\Documents\py\apibe\Venv\Lib\site-packages\cryptography\fernet.py", line 84, in decrypt
    timestamp, data = Fernet._get_unverified_token_data(token)
                      ~~~~~~~~~~~~~~~~~~~~~~~~~~~~~~~~~^^^^^^^
  File "C:\Users\JJH\OneDrive - Poyner Spruill\Documents\py\apibe\Venv\Lib\site-packages\cryptography\fernet.py", line 118, in _get_unverified_token_data
    raise InvalidToken
cryptography.fernet.InvalidToken
2024-10-20 01:44:42,301 [INFO]: C:\Users\JJH\OneDrive - Poyner Spruill\Documents\py\apibe\api\user_system\views.py changed, reloading.
2024-10-20 01:44:52,540 [ERROR]: Internal Server Error: /api/auth/validation
Traceback (most recent call last):
  File "C:\Users\JJH\OneDrive - Poyner Spruill\Documents\py\apibe\Venv\Lib\site-packages\django\core\handlers\exception.py", line 55, in inner
    response = get_response(request)
  File "C:\Users\JJH\OneDrive - Poyner Spruill\Documents\py\apibe\Venv\Lib\site-packages\django\core\handlers\base.py", line 197, in _get_response
    response = wrapped_callback(request, *callback_args, **callback_kwargs)
  File "C:\Users\JJH\OneDrive - Poyner Spruill\Documents\py\apibe\Venv\Lib\site-packages\django\views\decorators\csrf.py", line 65, in _view_wrapper
    return view_func(request, *args, **kwargs)
  File "C:\Users\JJH\OneDrive - Poyner Spruill\Documents\py\apibe\Venv\Lib\site-packages\django\views\generic\base.py", line 104, in view
    return self.dispatch(request, *args, **kwargs)
           ~~~~~~~~~~~~~^^^^^^^^^^^^^^^^^^^^^^^^^^
  File "C:\Users\JJH\OneDrive - Poyner Spruill\Documents\py\apibe\Venv\Lib\site-packages\rest_framework\views.py", line 509, in dispatch
    response = self.handle_exception(exc)
  File "C:\Users\JJH\OneDrive - Poyner Spruill\Documents\py\apibe\Venv\Lib\site-packages\rest_framework\views.py", line 469, in handle_exception
    self.raise_uncaught_exception(exc)
    ~~~~~~~~~~~~~~~~~~~~~~~~~~~~~^^^^^
  File "C:\Users\JJH\OneDrive - Poyner Spruill\Documents\py\apibe\Venv\Lib\site-packages\rest_framework\views.py", line 480, in raise_uncaught_exception
    raise exc
  File "C:\Users\JJH\OneDrive - Poyner Spruill\Documents\py\apibe\Venv\Lib\site-packages\rest_framework\views.py", line 506, in dispatch
    response = handler(request, *args, **kwargs)
  File "C:\Users\JJH\OneDrive - Poyner Spruill\Documents\py\apibe\Venv\Lib\site-packages\rest_framework\decorators.py", line 50, in handler
    return func(*args, **kwargs)
  File "C:\Users\JJH\OneDrive - Poyner Spruill\Documents\py\apibe\api\user_system\views.py", line 151, in user_validation
    access_token = encrypt_key.decrypt(linkage.key).decode('utf-8')
                   ~~~~~~~~~~~~~~~~~~~^^^^^^^^^^^^^
  File "C:\Users\JJH\OneDrive - Poyner Spruill\Documents\py\apibe\Venv\Lib\site-packages\cryptography\fernet.py", line 84, in decrypt
    timestamp, data = Fernet._get_unverified_token_data(token)
                      ~~~~~~~~~~~~~~~~~~~~~~~~~~~~~~~~~^^^^^^^
  File "C:\Users\JJH\OneDrive - Poyner Spruill\Documents\py\apibe\Venv\Lib\site-packages\cryptography\fernet.py", line 118, in _get_unverified_token_data
    raise InvalidToken
cryptography.fernet.InvalidToken
2024-10-20 01:45:00,091 [ERROR]: Internal Server Error: /api/auth/validation
Traceback (most recent call last):
  File "C:\Users\JJH\OneDrive - Poyner Spruill\Documents\py\apibe\Venv\Lib\site-packages\django\core\handlers\exception.py", line 55, in inner
    response = get_response(request)
  File "C:\Users\JJH\OneDrive - Poyner Spruill\Documents\py\apibe\Venv\Lib\site-packages\django\core\handlers\base.py", line 197, in _get_response
    response = wrapped_callback(request, *callback_args, **callback_kwargs)
  File "C:\Users\JJH\OneDrive - Poyner Spruill\Documents\py\apibe\Venv\Lib\site-packages\django\views\decorators\csrf.py", line 65, in _view_wrapper
    return view_func(request, *args, **kwargs)
  File "C:\Users\JJH\OneDrive - Poyner Spruill\Documents\py\apibe\Venv\Lib\site-packages\django\views\generic\base.py", line 104, in view
    return self.dispatch(request, *args, **kwargs)
           ~~~~~~~~~~~~~^^^^^^^^^^^^^^^^^^^^^^^^^^
  File "C:\Users\JJH\OneDrive - Poyner Spruill\Documents\py\apibe\Venv\Lib\site-packages\rest_framework\views.py", line 509, in dispatch
    response = self.handle_exception(exc)
  File "C:\Users\JJH\OneDrive - Poyner Spruill\Documents\py\apibe\Venv\Lib\site-packages\rest_framework\views.py", line 469, in handle_exception
    self.raise_uncaught_exception(exc)
    ~~~~~~~~~~~~~~~~~~~~~~~~~~~~~^^^^^
  File "C:\Users\JJH\OneDrive - Poyner Spruill\Documents\py\apibe\Venv\Lib\site-packages\rest_framework\views.py", line 480, in raise_uncaught_exception
    raise exc
  File "C:\Users\JJH\OneDrive - Poyner Spruill\Documents\py\apibe\Venv\Lib\site-packages\rest_framework\views.py", line 506, in dispatch
    response = handler(request, *args, **kwargs)
  File "C:\Users\JJH\OneDrive - Poyner Spruill\Documents\py\apibe\Venv\Lib\site-packages\rest_framework\decorators.py", line 50, in handler
    return func(*args, **kwargs)
  File "C:\Users\JJH\OneDrive - Poyner Spruill\Documents\py\apibe\api\user_system\views.py", line 151, in user_validation
    access_token = encrypt_key.decrypt(linkage.key).decode('utf-8')
                   ~~~~~~~~~~~~~~~~~~~^^^^^^^^^^^^^
  File "C:\Users\JJH\OneDrive - Poyner Spruill\Documents\py\apibe\Venv\Lib\site-packages\cryptography\fernet.py", line 84, in decrypt
    timestamp, data = Fernet._get_unverified_token_data(token)
                      ~~~~~~~~~~~~~~~~~~~~~~~~~~~~~~~~~^^^^^^^
  File "C:\Users\JJH\OneDrive - Poyner Spruill\Documents\py\apibe\Venv\Lib\site-packages\cryptography\fernet.py", line 118, in _get_unverified_token_data
    raise InvalidToken
cryptography.fernet.InvalidToken
2024-10-20 01:45:13,570 [ERROR]: Internal Server Error: /api/auth/validation
Traceback (most recent call last):
  File "C:\Users\JJH\OneDrive - Poyner Spruill\Documents\py\apibe\Venv\Lib\site-packages\django\core\handlers\exception.py", line 55, in inner
    response = get_response(request)
  File "C:\Users\JJH\OneDrive - Poyner Spruill\Documents\py\apibe\Venv\Lib\site-packages\django\core\handlers\base.py", line 197, in _get_response
    response = wrapped_callback(request, *callback_args, **callback_kwargs)
  File "C:\Users\JJH\OneDrive - Poyner Spruill\Documents\py\apibe\Venv\Lib\site-packages\django\views\decorators\csrf.py", line 65, in _view_wrapper
    return view_func(request, *args, **kwargs)
  File "C:\Users\JJH\OneDrive - Poyner Spruill\Documents\py\apibe\Venv\Lib\site-packages\django\views\generic\base.py", line 104, in view
    return self.dispatch(request, *args, **kwargs)
           ~~~~~~~~~~~~~^^^^^^^^^^^^^^^^^^^^^^^^^^
  File "C:\Users\JJH\OneDrive - Poyner Spruill\Documents\py\apibe\Venv\Lib\site-packages\rest_framework\views.py", line 509, in dispatch
    response = self.handle_exception(exc)
  File "C:\Users\JJH\OneDrive - Poyner Spruill\Documents\py\apibe\Venv\Lib\site-packages\rest_framework\views.py", line 469, in handle_exception
    self.raise_uncaught_exception(exc)
    ~~~~~~~~~~~~~~~~~~~~~~~~~~~~~^^^^^
  File "C:\Users\JJH\OneDrive - Poyner Spruill\Documents\py\apibe\Venv\Lib\site-packages\rest_framework\views.py", line 480, in raise_uncaught_exception
    raise exc
  File "C:\Users\JJH\OneDrive - Poyner Spruill\Documents\py\apibe\Venv\Lib\site-packages\rest_framework\views.py", line 506, in dispatch
    response = handler(request, *args, **kwargs)
  File "C:\Users\JJH\OneDrive - Poyner Spruill\Documents\py\apibe\Venv\Lib\site-packages\rest_framework\decorators.py", line 50, in handler
    return func(*args, **kwargs)
  File "C:\Users\JJH\OneDrive - Poyner Spruill\Documents\py\apibe\api\user_system\views.py", line 151, in user_validation
    access_token = encrypt_key.decrypt(linkage.key).decode('utf-8')
                   ~~~~~~~~~~~~~~~~~~~^^^^^^^^^^^^^
  File "C:\Users\JJH\OneDrive - Poyner Spruill\Documents\py\apibe\Venv\Lib\site-packages\cryptography\fernet.py", line 84, in decrypt
    timestamp, data = Fernet._get_unverified_token_data(token)
                      ~~~~~~~~~~~~~~~~~~~~~~~~~~~~~~~~~^^^^^^^
  File "C:\Users\JJH\OneDrive - Poyner Spruill\Documents\py\apibe\Venv\Lib\site-packages\cryptography\fernet.py", line 118, in _get_unverified_token_data
    raise InvalidToken
cryptography.fernet.InvalidToken
2024-10-20 01:50:41,425 [INFO]: C:\Users\JJH\OneDrive - Poyner Spruill\Documents\py\apibe\api\user_system\models.py changed, reloading.
2024-10-20 01:53:19,070 [ERROR]: Internal Server Error: /api/auth/validate_access
Traceback (most recent call last):
  File "C:\Users\JJH\OneDrive - Poyner Spruill\Documents\py\apibe\Venv\Lib\site-packages\django\core\handlers\exception.py", line 55, in inner
    response = get_response(request)
  File "C:\Users\JJH\OneDrive - Poyner Spruill\Documents\py\apibe\Venv\Lib\site-packages\django\core\handlers\base.py", line 220, in _get_response
    response = response.render()
  File "C:\Users\JJH\OneDrive - Poyner Spruill\Documents\py\apibe\Venv\Lib\site-packages\django\template\response.py", line 114, in render
    self.content = self.rendered_content
                   ^^^^^^^^^^^^^^^^^^^^^
  File "C:\Users\JJH\OneDrive - Poyner Spruill\Documents\py\apibe\Venv\Lib\site-packages\rest_framework\response.py", line 74, in rendered_content
    ret = renderer.render(self.data, accepted_media_type, context)
  File "C:\Users\JJH\OneDrive - Poyner Spruill\Documents\py\apibe\Venv\Lib\site-packages\rest_framework\renderers.py", line 100, in render
    ret = json.dumps(
        data, cls=self.encoder_class,
        indent=indent, ensure_ascii=self.ensure_ascii,
        allow_nan=not self.strict, separators=separators
    )
  File "C:\Users\JJH\OneDrive - Poyner Spruill\Documents\py\apibe\Venv\Lib\site-packages\rest_framework\utils\json.py", line 25, in dumps
    return json.dumps(*args, **kwargs)
           ~~~~~~~~~~^^^^^^^^^^^^^^^^^
  File "C:\Users\JJH\AppData\Local\Programs\Python\Python313\Lib\json\__init__.py", line 238, in dumps
    **kw).encode(obj)
          ~~~~~~^^^^^
  File "C:\Users\JJH\AppData\Local\Programs\Python\Python313\Lib\json\encoder.py", line 200, in encode
    chunks = self.iterencode(o, _one_shot=True)
  File "C:\Users\JJH\AppData\Local\Programs\Python\Python313\Lib\json\encoder.py", line 261, in iterencode
    return _iterencode(o, 0)
  File "C:\Users\JJH\OneDrive - Poyner Spruill\Documents\py\apibe\Venv\Lib\site-packages\rest_framework\utils\encoders.py", line 67, in default
    return super().default(obj)
           ~~~~~~~~~~~~~~~^^^^^
  File "C:\Users\JJH\AppData\Local\Programs\Python\Python313\Lib\json\encoder.py", line 180, in default
    raise TypeError(f'Object of type {o.__class__.__name__} '
                    f'is not JSON serializable')
TypeError: Object of type DoesNotExist is not JSON serializable
2024-10-20 01:58:51,866 [INFO]: C:\Users\JJH\OneDrive - Poyner Spruill\Documents\py\apibe\api\user_system\views.py changed, reloading.
2024-10-20 01:58:57,425 [ERROR]: Internal Server Error: /api/auth/validate_access
Traceback (most recent call last):
  File "C:\Users\JJH\OneDrive - Poyner Spruill\Documents\py\apibe\Venv\Lib\site-packages\django\core\handlers\exception.py", line 55, in inner
    response = get_response(request)
  File "C:\Users\JJH\OneDrive - Poyner Spruill\Documents\py\apibe\Venv\Lib\site-packages\django\core\handlers\base.py", line 220, in _get_response
    response = response.render()
  File "C:\Users\JJH\OneDrive - Poyner Spruill\Documents\py\apibe\Venv\Lib\site-packages\django\template\response.py", line 114, in render
    self.content = self.rendered_content
                   ^^^^^^^^^^^^^^^^^^^^^
  File "C:\Users\JJH\OneDrive - Poyner Spruill\Documents\py\apibe\Venv\Lib\site-packages\rest_framework\response.py", line 74, in rendered_content
    ret = renderer.render(self.data, accepted_media_type, context)
  File "C:\Users\JJH\OneDrive - Poyner Spruill\Documents\py\apibe\Venv\Lib\site-packages\rest_framework\renderers.py", line 100, in render
    ret = json.dumps(
        data, cls=self.encoder_class,
        indent=indent, ensure_ascii=self.ensure_ascii,
        allow_nan=not self.strict, separators=separators
    )
  File "C:\Users\JJH\OneDrive - Poyner Spruill\Documents\py\apibe\Venv\Lib\site-packages\rest_framework\utils\json.py", line 25, in dumps
    return json.dumps(*args, **kwargs)
           ~~~~~~~~~~^^^^^^^^^^^^^^^^^
  File "C:\Users\JJH\AppData\Local\Programs\Python\Python313\Lib\json\__init__.py", line 238, in dumps
    **kw).encode(obj)
          ~~~~~~^^^^^
  File "C:\Users\JJH\AppData\Local\Programs\Python\Python313\Lib\json\encoder.py", line 200, in encode
    chunks = self.iterencode(o, _one_shot=True)
  File "C:\Users\JJH\AppData\Local\Programs\Python\Python313\Lib\json\encoder.py", line 261, in iterencode
    return _iterencode(o, 0)
  File "C:\Users\JJH\OneDrive - Poyner Spruill\Documents\py\apibe\Venv\Lib\site-packages\rest_framework\utils\encoders.py", line 67, in default
    return super().default(obj)
           ~~~~~~~~~~~~~~~^^^^^
  File "C:\Users\JJH\AppData\Local\Programs\Python\Python313\Lib\json\encoder.py", line 180, in default
    raise TypeError(f'Object of type {o.__class__.__name__} '
                    f'is not JSON serializable')
TypeError: Object of type DoesNotExist is not JSON serializable
2024-10-20 02:00:07,986 [INFO]: C:\Users\JJH\OneDrive - Poyner Spruill\Documents\py\apibe\api\user_system\views.py changed, reloading.
2024-10-20 02:00:14,109 [WARNING]: Bad Request: /api/auth/validate_access
2024-10-20 02:00:16,424 [WARNING]: Bad Request: /api/auth/validate_access
2024-10-20 02:00:32,357 [WARNING]: Bad Request: /api/auth/validate_access
2024-10-20 02:00:57,144 [WARNING]: Bad Request: /api/auth/validate_access
2024-10-20 02:01:58,281 [INFO]: C:\Users\JJH\OneDrive - Poyner Spruill\Documents\py\apibe\api\user_system\views.py changed, reloading.
2024-10-20 02:02:07,119 [WARNING]: Bad Request: /api/auth/validate_access
2024-10-20 02:02:21,188 [INFO]: C:\Users\JJH\OneDrive - Poyner Spruill\Documents\py\apibe\api\user_system\views.py changed, reloading.
2024-10-20 02:03:14,206 [WARNING]: Bad Request: /api/auth/validate_access
2024-10-20 02:05:07,250 [INFO]: C:\Users\JJH\OneDrive - Poyner Spruill\Documents\py\apibe\api\user_system\views.py changed, reloading.
2024-10-20 02:06:24,819 [WARNING]: Bad Request: /api/auth/validate_access
2024-10-20 02:07:06,623 [INFO]: C:\Users\JJH\OneDrive - Poyner Spruill\Documents\py\apibe\api\user_system\views.py changed, reloading.
2024-10-20 02:20:33,489 [INFO]: C:\Users\JJH\OneDrive - Poyner Spruill\Documents\py\apibe\api\user_system\views.py changed, reloading.
2024-10-20 02:24:41,161 [INFO]: C:\Users\JJH\OneDrive - Poyner Spruill\Documents\py\apibe\api\user_system\models.py changed, reloading.
2024-10-20 02:25:13,023 [INFO]: C:\Users\JJH\OneDrive - Poyner Spruill\Documents\py\apibe\api\user_system\views.py changed, reloading.
2024-10-20 02:25:40,173 [INFO]: C:\Users\JJH\OneDrive - Poyner Spruill\Documents\py\apibe\api\user_system\models.py changed, reloading.
2024-10-20 02:27:38,162 [INFO]: C:\Users\JJH\OneDrive - Poyner Spruill\Documents\py\apibe\api\user_system\views.py changed, reloading.
2024-10-20 02:31:00,167 [INFO]: C:\Users\JJH\OneDrive - Poyner Spruill\Documents\py\apibe\api\user_system\views.py changed, reloading.
2024-10-20 02:31:16,319 [INFO]: C:\Users\JJH\OneDrive - Poyner Spruill\Documents\py\apibe\api\user_system\views.py changed, reloading.
2024-10-20 02:31:21,920 [ERROR]: Internal Server Error: /api/auth/validation
Traceback (most recent call last):
  File "C:\Users\JJH\OneDrive - Poyner Spruill\Documents\py\apibe\Venv\Lib\site-packages\django\core\handlers\exception.py", line 55, in inner
    response = get_response(request)
  File "C:\Users\JJH\OneDrive - Poyner Spruill\Documents\py\apibe\Venv\Lib\site-packages\django\core\handlers\base.py", line 197, in _get_response
    response = wrapped_callback(request, *callback_args, **callback_kwargs)
  File "C:\Users\JJH\OneDrive - Poyner Spruill\Documents\py\apibe\Venv\Lib\site-packages\django\views\decorators\csrf.py", line 65, in _view_wrapper
    return view_func(request, *args, **kwargs)
  File "C:\Users\JJH\OneDrive - Poyner Spruill\Documents\py\apibe\Venv\Lib\site-packages\django\views\generic\base.py", line 104, in view
    return self.dispatch(request, *args, **kwargs)
           ~~~~~~~~~~~~~^^^^^^^^^^^^^^^^^^^^^^^^^^
  File "C:\Users\JJH\OneDrive - Poyner Spruill\Documents\py\apibe\Venv\Lib\site-packages\rest_framework\views.py", line 509, in dispatch
    response = self.handle_exception(exc)
  File "C:\Users\JJH\OneDrive - Poyner Spruill\Documents\py\apibe\Venv\Lib\site-packages\rest_framework\views.py", line 469, in handle_exception
    self.raise_uncaught_exception(exc)
    ~~~~~~~~~~~~~~~~~~~~~~~~~~~~~^^^^^
  File "C:\Users\JJH\OneDrive - Poyner Spruill\Documents\py\apibe\Venv\Lib\site-packages\rest_framework\views.py", line 480, in raise_uncaught_exception
    raise exc
  File "C:\Users\JJH\OneDrive - Poyner Spruill\Documents\py\apibe\Venv\Lib\site-packages\rest_framework\views.py", line 506, in dispatch
    response = handler(request, *args, **kwargs)
  File "C:\Users\JJH\OneDrive - Poyner Spruill\Documents\py\apibe\Venv\Lib\site-packages\rest_framework\decorators.py", line 50, in handler
    return func(*args, **kwargs)
  File "C:\Users\JJH\OneDrive - Poyner Spruill\Documents\py\apibe\api\user_system\views.py", line 176, in user_validation
    get_or_refresh_access_token(linkage.key)
    ~~~~~~~~~~~~~~~~~~~~~~~~~~~^^^^^^^^^^^^^
  File "C:\Users\JJH\OneDrive - Poyner Spruill\Documents\py\apibe\api\user_system\views.py", line 43, in get_or_refresh_access_token
    expired_time_offset = timedelta(seconds=linkage.expiery)
                                            ^^^^^^^^^^^^^^^
AttributeError: 'str' object has no attribute 'expiery'
2024-10-20 02:31:41,059 [INFO]: C:\Users\JJH\OneDrive - Poyner Spruill\Documents\py\apibe\api\user_system\views.py changed, reloading.
2024-10-20 02:31:48,287 [ERROR]: Internal Server Error: /api/auth/validation
Traceback (most recent call last):
  File "C:\Users\JJH\OneDrive - Poyner Spruill\Documents\py\apibe\Venv\Lib\site-packages\django\core\handlers\exception.py", line 55, in inner
    response = get_response(request)
  File "C:\Users\JJH\OneDrive - Poyner Spruill\Documents\py\apibe\Venv\Lib\site-packages\django\core\handlers\base.py", line 197, in _get_response
    response = wrapped_callback(request, *callback_args, **callback_kwargs)
  File "C:\Users\JJH\OneDrive - Poyner Spruill\Documents\py\apibe\Venv\Lib\site-packages\django\views\decorators\csrf.py", line 65, in _view_wrapper
    return view_func(request, *args, **kwargs)
  File "C:\Users\JJH\OneDrive - Poyner Spruill\Documents\py\apibe\Venv\Lib\site-packages\django\views\generic\base.py", line 104, in view
    return self.dispatch(request, *args, **kwargs)
           ~~~~~~~~~~~~~^^^^^^^^^^^^^^^^^^^^^^^^^^
  File "C:\Users\JJH\OneDrive - Poyner Spruill\Documents\py\apibe\Venv\Lib\site-packages\rest_framework\views.py", line 509, in dispatch
    response = self.handle_exception(exc)
  File "C:\Users\JJH\OneDrive - Poyner Spruill\Documents\py\apibe\Venv\Lib\site-packages\rest_framework\views.py", line 469, in handle_exception
    self.raise_uncaught_exception(exc)
    ~~~~~~~~~~~~~~~~~~~~~~~~~~~~~^^^^^
  File "C:\Users\JJH\OneDrive - Poyner Spruill\Documents\py\apibe\Venv\Lib\site-packages\rest_framework\views.py", line 480, in raise_uncaught_exception
    raise exc
  File "C:\Users\JJH\OneDrive - Poyner Spruill\Documents\py\apibe\Venv\Lib\site-packages\rest_framework\views.py", line 506, in dispatch
    response = handler(request, *args, **kwargs)
  File "C:\Users\JJH\OneDrive - Poyner Spruill\Documents\py\apibe\Venv\Lib\site-packages\rest_framework\decorators.py", line 50, in handler
    return func(*args, **kwargs)
  File "C:\Users\JJH\OneDrive - Poyner Spruill\Documents\py\apibe\api\user_system\views.py", line 176, in user_validation
    get_or_refresh_access_token(linkage)
    ~~~~~~~~~~~~~~~~~~~~~~~~~~~^^^^^^^^^
  File "C:\Users\JJH\OneDrive - Poyner Spruill\Documents\py\apibe\api\user_system\views.py", line 47, in get_or_refresh_access_token
    if is_expired > datetime.now():
       ^^^^^^^^^^^^^^^^^^^^^^^^^^^
TypeError: can't compare offset-naive and offset-aware datetimes
2024-10-20 02:32:00,545 [ERROR]: Internal Server Error: /api/auth/validation
Traceback (most recent call last):
  File "C:\Users\JJH\OneDrive - Poyner Spruill\Documents\py\apibe\Venv\Lib\site-packages\django\core\handlers\exception.py", line 55, in inner
    response = get_response(request)
  File "C:\Users\JJH\OneDrive - Poyner Spruill\Documents\py\apibe\Venv\Lib\site-packages\django\core\handlers\base.py", line 197, in _get_response
    response = wrapped_callback(request, *callback_args, **callback_kwargs)
  File "C:\Users\JJH\OneDrive - Poyner Spruill\Documents\py\apibe\Venv\Lib\site-packages\django\views\decorators\csrf.py", line 65, in _view_wrapper
    return view_func(request, *args, **kwargs)
  File "C:\Users\JJH\OneDrive - Poyner Spruill\Documents\py\apibe\Venv\Lib\site-packages\django\views\generic\base.py", line 104, in view
    return self.dispatch(request, *args, **kwargs)
           ~~~~~~~~~~~~~^^^^^^^^^^^^^^^^^^^^^^^^^^
  File "C:\Users\JJH\OneDrive - Poyner Spruill\Documents\py\apibe\Venv\Lib\site-packages\rest_framework\views.py", line 509, in dispatch
    response = self.handle_exception(exc)
  File "C:\Users\JJH\OneDrive - Poyner Spruill\Documents\py\apibe\Venv\Lib\site-packages\rest_framework\views.py", line 469, in handle_exception
    self.raise_uncaught_exception(exc)
    ~~~~~~~~~~~~~~~~~~~~~~~~~~~~~^^^^^
  File "C:\Users\JJH\OneDrive - Poyner Spruill\Documents\py\apibe\Venv\Lib\site-packages\rest_framework\views.py", line 480, in raise_uncaught_exception
    raise exc
  File "C:\Users\JJH\OneDrive - Poyner Spruill\Documents\py\apibe\Venv\Lib\site-packages\rest_framework\views.py", line 506, in dispatch
    response = handler(request, *args, **kwargs)
  File "C:\Users\JJH\OneDrive - Poyner Spruill\Documents\py\apibe\Venv\Lib\site-packages\rest_framework\decorators.py", line 50, in handler
    return func(*args, **kwargs)
  File "C:\Users\JJH\OneDrive - Poyner Spruill\Documents\py\apibe\api\user_system\views.py", line 176, in user_validation
    get_or_refresh_access_token(linkage)
    ~~~~~~~~~~~~~~~~~~~~~~~~~~~^^^^^^^^^
  File "C:\Users\JJH\OneDrive - Poyner Spruill\Documents\py\apibe\api\user_system\views.py", line 47, in get_or_refresh_access_token
    if is_expired > datetime.now():
       ^^^^^^^^^^^^^^^^^^^^^^^^^^^
TypeError: can't compare offset-naive and offset-aware datetimes
2024-10-20 02:33:48,982 [INFO]: C:\Users\JJH\OneDrive - Poyner Spruill\Documents\py\apibe\api\user_system\views.py changed, reloading.
2024-10-20 02:33:59,704 [INFO]: C:\Users\JJH\OneDrive - Poyner Spruill\Documents\py\apibe\api\user_system\views.py changed, reloading.
2024-10-20 02:34:25,915 [ERROR]: Internal Server Error: /api/auth/validation
Traceback (most recent call last):
  File "C:\Users\JJH\OneDrive - Poyner Spruill\Documents\py\apibe\Venv\Lib\site-packages\django\core\handlers\exception.py", line 55, in inner
    response = get_response(request)
  File "C:\Users\JJH\OneDrive - Poyner Spruill\Documents\py\apibe\Venv\Lib\site-packages\django\core\handlers\base.py", line 197, in _get_response
    response = wrapped_callback(request, *callback_args, **callback_kwargs)
  File "C:\Users\JJH\OneDrive - Poyner Spruill\Documents\py\apibe\Venv\Lib\site-packages\django\views\decorators\csrf.py", line 65, in _view_wrapper
    return view_func(request, *args, **kwargs)
  File "C:\Users\JJH\OneDrive - Poyner Spruill\Documents\py\apibe\Venv\Lib\site-packages\django\views\generic\base.py", line 104, in view
    return self.dispatch(request, *args, **kwargs)
           ~~~~~~~~~~~~~^^^^^^^^^^^^^^^^^^^^^^^^^^
  File "C:\Users\JJH\OneDrive - Poyner Spruill\Documents\py\apibe\Venv\Lib\site-packages\rest_framework\views.py", line 509, in dispatch
    response = self.handle_exception(exc)
  File "C:\Users\JJH\OneDrive - Poyner Spruill\Documents\py\apibe\Venv\Lib\site-packages\rest_framework\views.py", line 469, in handle_exception
    self.raise_uncaught_exception(exc)
    ~~~~~~~~~~~~~~~~~~~~~~~~~~~~~^^^^^
  File "C:\Users\JJH\OneDrive - Poyner Spruill\Documents\py\apibe\Venv\Lib\site-packages\rest_framework\views.py", line 480, in raise_uncaught_exception
    raise exc
  File "C:\Users\JJH\OneDrive - Poyner Spruill\Documents\py\apibe\Venv\Lib\site-packages\rest_framework\views.py", line 506, in dispatch
    response = handler(request, *args, **kwargs)
  File "C:\Users\JJH\OneDrive - Poyner Spruill\Documents\py\apibe\Venv\Lib\site-packages\rest_framework\decorators.py", line 50, in handler
    return func(*args, **kwargs)
  File "C:\Users\JJH\OneDrive - Poyner Spruill\Documents\py\apibe\api\user_system\views.py", line 176, in user_validation
    get_or_refresh_access_token(linkage)
    ~~~~~~~~~~~~~~~~~~~~~~~~~~~^^^^^^^^^
  File "C:\Users\JJH\OneDrive - Poyner Spruill\Documents\py\apibe\api\user_system\views.py", line 44, in get_or_refresh_access_token
    is_expired = datetime(linkage.timestamp) + expired_time_offset
                 ~~~~~~~~^^^^^^^^^^^^^^^^^^^
TypeError: 'datetime.datetime' object cannot be interpreted as an integer
2024-10-20 02:35:24,631 [INFO]: C:\Users\JJH\OneDrive - Poyner Spruill\Documents\py\apibe\api\user_system\views.py changed, reloading.
2024-10-20 02:35:32,942 [INFO]: C:\Users\JJH\OneDrive - Poyner Spruill\Documents\py\apibe\api\user_system\views.py changed, reloading.
2024-10-20 02:35:41,225 [ERROR]: Internal Server Error: /api/auth/validation
Traceback (most recent call last):
  File "C:\Users\JJH\OneDrive - Poyner Spruill\Documents\py\apibe\Venv\Lib\site-packages\django\core\handlers\exception.py", line 55, in inner
    response = get_response(request)
  File "C:\Users\JJH\OneDrive - Poyner Spruill\Documents\py\apibe\Venv\Lib\site-packages\django\core\handlers\base.py", line 197, in _get_response
    response = wrapped_callback(request, *callback_args, **callback_kwargs)
  File "C:\Users\JJH\OneDrive - Poyner Spruill\Documents\py\apibe\Venv\Lib\site-packages\django\views\decorators\csrf.py", line 65, in _view_wrapper
    return view_func(request, *args, **kwargs)
  File "C:\Users\JJH\OneDrive - Poyner Spruill\Documents\py\apibe\Venv\Lib\site-packages\django\views\generic\base.py", line 104, in view
    return self.dispatch(request, *args, **kwargs)
           ~~~~~~~~~~~~~^^^^^^^^^^^^^^^^^^^^^^^^^^
  File "C:\Users\JJH\OneDrive - Poyner Spruill\Documents\py\apibe\Venv\Lib\site-packages\rest_framework\views.py", line 509, in dispatch
    response = self.handle_exception(exc)
  File "C:\Users\JJH\OneDrive - Poyner Spruill\Documents\py\apibe\Venv\Lib\site-packages\rest_framework\views.py", line 469, in handle_exception
    self.raise_uncaught_exception(exc)
    ~~~~~~~~~~~~~~~~~~~~~~~~~~~~~^^^^^
  File "C:\Users\JJH\OneDrive - Poyner Spruill\Documents\py\apibe\Venv\Lib\site-packages\rest_framework\views.py", line 480, in raise_uncaught_exception
    raise exc
  File "C:\Users\JJH\OneDrive - Poyner Spruill\Documents\py\apibe\Venv\Lib\site-packages\rest_framework\views.py", line 506, in dispatch
    response = handler(request, *args, **kwargs)
  File "C:\Users\JJH\OneDrive - Poyner Spruill\Documents\py\apibe\Venv\Lib\site-packages\rest_framework\decorators.py", line 50, in handler
    return func(*args, **kwargs)
  File "C:\Users\JJH\OneDrive - Poyner Spruill\Documents\py\apibe\api\user_system\views.py", line 177, in user_validation
    get_or_refresh_access_token(linkage)
    ~~~~~~~~~~~~~~~~~~~~~~~~~~~^^^^^^^^^
  File "C:\Users\JJH\OneDrive - Poyner Spruill\Documents\py\apibe\api\user_system\views.py", line 45, in get_or_refresh_access_token
    is_expired = datetime(str(linkage.timestamp)) + expired_time_offset
                 ~~~~~~~~^^^^^^^^^^^^^^^^^^^^^^^^
TypeError: 'str' object cannot be interpreted as an integer
2024-10-20 02:36:00,387 [INFO]: C:\Users\JJH\OneDrive - Poyner Spruill\Documents\py\apibe\api\user_system\views.py changed, reloading.
2024-10-20 02:36:10,747 [ERROR]: Internal Server Error: /api/auth/validation
Traceback (most recent call last):
  File "C:\Users\JJH\OneDrive - Poyner Spruill\Documents\py\apibe\Venv\Lib\site-packages\django\core\handlers\exception.py", line 55, in inner
    response = get_response(request)
  File "C:\Users\JJH\OneDrive - Poyner Spruill\Documents\py\apibe\Venv\Lib\site-packages\django\core\handlers\base.py", line 197, in _get_response
    response = wrapped_callback(request, *callback_args, **callback_kwargs)
  File "C:\Users\JJH\OneDrive - Poyner Spruill\Documents\py\apibe\Venv\Lib\site-packages\django\views\decorators\csrf.py", line 65, in _view_wrapper
    return view_func(request, *args, **kwargs)
  File "C:\Users\JJH\OneDrive - Poyner Spruill\Documents\py\apibe\Venv\Lib\site-packages\django\views\generic\base.py", line 104, in view
    return self.dispatch(request, *args, **kwargs)
           ~~~~~~~~~~~~~^^^^^^^^^^^^^^^^^^^^^^^^^^
  File "C:\Users\JJH\OneDrive - Poyner Spruill\Documents\py\apibe\Venv\Lib\site-packages\rest_framework\views.py", line 509, in dispatch
    response = self.handle_exception(exc)
  File "C:\Users\JJH\OneDrive - Poyner Spruill\Documents\py\apibe\Venv\Lib\site-packages\rest_framework\views.py", line 469, in handle_exception
    self.raise_uncaught_exception(exc)
    ~~~~~~~~~~~~~~~~~~~~~~~~~~~~~^^^^^
  File "C:\Users\JJH\OneDrive - Poyner Spruill\Documents\py\apibe\Venv\Lib\site-packages\rest_framework\views.py", line 480, in raise_uncaught_exception
    raise exc
  File "C:\Users\JJH\OneDrive - Poyner Spruill\Documents\py\apibe\Venv\Lib\site-packages\rest_framework\views.py", line 506, in dispatch
    response = handler(request, *args, **kwargs)
  File "C:\Users\JJH\OneDrive - Poyner Spruill\Documents\py\apibe\Venv\Lib\site-packages\rest_framework\decorators.py", line 50, in handler
    return func(*args, **kwargs)
  File "C:\Users\JJH\OneDrive - Poyner Spruill\Documents\py\apibe\api\user_system\views.py", line 177, in user_validation
    get_or_refresh_access_token(linkage)
    ~~~~~~~~~~~~~~~~~~~~~~~~~~~^^^^^^^^^
  File "C:\Users\JJH\OneDrive - Poyner Spruill\Documents\py\apibe\api\user_system\views.py", line 45, in get_or_refresh_access_token
    is_expired = datetime(str(linkage.timestamp)) + expired_time_offset
                 ~~~~~~~~^^^^^^^^^^^^^^^^^^^^^^^^
TypeError: 'str' object cannot be interpreted as an integer
2024-10-20 02:38:49,465 [INFO]: C:\Users\JJH\OneDrive - Poyner Spruill\Documents\py\apibe\api\user_system\views.py changed, reloading.
2024-10-20 02:39:00,714 [ERROR]: Internal Server Error: /api/auth/validation
Traceback (most recent call last):
  File "C:\Users\JJH\OneDrive - Poyner Spruill\Documents\py\apibe\Venv\Lib\site-packages\django\core\handlers\exception.py", line 55, in inner
    response = get_response(request)
  File "C:\Users\JJH\OneDrive - Poyner Spruill\Documents\py\apibe\Venv\Lib\site-packages\django\core\handlers\base.py", line 197, in _get_response
    response = wrapped_callback(request, *callback_args, **callback_kwargs)
  File "C:\Users\JJH\OneDrive - Poyner Spruill\Documents\py\apibe\Venv\Lib\site-packages\django\views\decorators\csrf.py", line 65, in _view_wrapper
    return view_func(request, *args, **kwargs)
  File "C:\Users\JJH\OneDrive - Poyner Spruill\Documents\py\apibe\Venv\Lib\site-packages\django\views\generic\base.py", line 104, in view
    return self.dispatch(request, *args, **kwargs)
           ~~~~~~~~~~~~~^^^^^^^^^^^^^^^^^^^^^^^^^^
  File "C:\Users\JJH\OneDrive - Poyner Spruill\Documents\py\apibe\Venv\Lib\site-packages\rest_framework\views.py", line 509, in dispatch
    response = self.handle_exception(exc)
  File "C:\Users\JJH\OneDrive - Poyner Spruill\Documents\py\apibe\Venv\Lib\site-packages\rest_framework\views.py", line 469, in handle_exception
    self.raise_uncaught_exception(exc)
    ~~~~~~~~~~~~~~~~~~~~~~~~~~~~~^^^^^
  File "C:\Users\JJH\OneDrive - Poyner Spruill\Documents\py\apibe\Venv\Lib\site-packages\rest_framework\views.py", line 480, in raise_uncaught_exception
    raise exc
  File "C:\Users\JJH\OneDrive - Poyner Spruill\Documents\py\apibe\Venv\Lib\site-packages\rest_framework\views.py", line 506, in dispatch
    response = handler(request, *args, **kwargs)
  File "C:\Users\JJH\OneDrive - Poyner Spruill\Documents\py\apibe\Venv\Lib\site-packages\rest_framework\decorators.py", line 50, in handler
    return func(*args, **kwargs)
  File "C:\Users\JJH\OneDrive - Poyner Spruill\Documents\py\apibe\api\user_system\views.py", line 184, in user_validation
    headers={'Authorization': 'Bearer ' + linkage.key},
                              ~~~~~~~~~~^~~~~~~~~~~~~
TypeError: can only concatenate str (not "bytes") to str
2024-10-20 02:39:57,652 [INFO]: C:\Users\JJH\OneDrive - Poyner Spruill\Documents\py\apibe\api\user_system\views.py changed, reloading.
2024-10-20 02:40:17,835 [INFO]: C:\Users\JJH\OneDrive - Poyner Spruill\Documents\py\apibe\api\user_system\views.py changed, reloading.
2024-10-20 02:40:23,898 [ERROR]: Internal Server Error: /api/auth/validation
Traceback (most recent call last):
  File "C:\Users\JJH\OneDrive - Poyner Spruill\Documents\py\apibe\Venv\Lib\site-packages\django\core\handlers\exception.py", line 55, in inner
    response = get_response(request)
  File "C:\Users\JJH\OneDrive - Poyner Spruill\Documents\py\apibe\Venv\Lib\site-packages\django\core\handlers\base.py", line 197, in _get_response
    response = wrapped_callback(request, *callback_args, **callback_kwargs)
  File "C:\Users\JJH\OneDrive - Poyner Spruill\Documents\py\apibe\Venv\Lib\site-packages\django\views\decorators\csrf.py", line 65, in _view_wrapper
    return view_func(request, *args, **kwargs)
  File "C:\Users\JJH\OneDrive - Poyner Spruill\Documents\py\apibe\Venv\Lib\site-packages\django\views\generic\base.py", line 104, in view
    return self.dispatch(request, *args, **kwargs)
           ~~~~~~~~~~~~~^^^^^^^^^^^^^^^^^^^^^^^^^^
  File "C:\Users\JJH\OneDrive - Poyner Spruill\Documents\py\apibe\Venv\Lib\site-packages\rest_framework\views.py", line 509, in dispatch
    response = self.handle_exception(exc)
  File "C:\Users\JJH\OneDrive - Poyner Spruill\Documents\py\apibe\Venv\Lib\site-packages\rest_framework\views.py", line 469, in handle_exception
    self.raise_uncaught_exception(exc)
    ~~~~~~~~~~~~~~~~~~~~~~~~~~~~~^^^^^
  File "C:\Users\JJH\OneDrive - Poyner Spruill\Documents\py\apibe\Venv\Lib\site-packages\rest_framework\views.py", line 480, in raise_uncaught_exception
    raise exc
  File "C:\Users\JJH\OneDrive - Poyner Spruill\Documents\py\apibe\Venv\Lib\site-packages\rest_framework\views.py", line 506, in dispatch
    response = handler(request, *args, **kwargs)
  File "C:\Users\JJH\OneDrive - Poyner Spruill\Documents\py\apibe\Venv\Lib\site-packages\rest_framework\decorators.py", line 50, in handler
    return func(*args, **kwargs)
  File "C:\Users\JJH\OneDrive - Poyner Spruill\Documents\py\apibe\api\user_system\views.py", line 184, in user_validation
    headers={'Authorization': 'Bearer ' + access_token},
                              ~~~~~~~~~~^~~~~~~~~~~~~~
TypeError: can only concatenate str (not "bytes") to str
2024-10-20 02:40:57,251 [INFO]: C:\Users\JJH\OneDrive - Poyner Spruill\Documents\py\apibe\api\user_system\views.py changed, reloading.
2024-10-20 02:41:06,760 [INFO]: C:\Users\JJH\OneDrive - Poyner Spruill\Documents\py\apibe\api\user_system\views.py changed, reloading.
2024-10-20 02:43:25,526 [INFO]: C:\Users\JJH\OneDrive - Poyner Spruill\Documents\py\apibe\api\user_system\views.py changed, reloading.
2024-10-20 02:45:52,185 [INFO]: C:\Users\JJH\OneDrive - Poyner Spruill\Documents\py\apibe\api\user_system\views.py changed, reloading.
2024-10-20 02:46:24,860 [INFO]: C:\Users\JJH\OneDrive - Poyner Spruill\Documents\py\apibe\api\user_system\models.py changed, reloading.
